Workbook

Sheet Attendance
B1: SUBJECT: IS 2
B2: COURSE/YEAR: BSIT 1D | D2: LECTURE ATTENDANCE
B3: TIME: 1:00 PM - 5:00 PM
B4: ROOM: COMPLAB 4
B5: UNITS: 2
C6: PRELIM (JANUARY-FEBRUARY) | L6: MIDTERM (FEBRUARY-MARCH) | U6: FINAL (MARCH-MAY)
A7: No. | B7: Student Name | C7: 46030 | D7: 46037 | E7: 46044 | F7: 46051 | G7: 46058 | H7: 46065 | J7: TOTAL | L7: 46086 | M7: 46093 | N7: 46100 | S7: TOTAL | U7: 46121 | V7: 46128 | W7: 46135 | X7: 46142 | AB7: TOTAL | AD7: OVERALL TOTAL
A8: 1 | B8: Alcantara, Albert Marquez | C8: 1 | D8: 1 | E8: 1 | F8: 0 | J8: =SUM(C8:H8) -> 3 | L8: 1 | M8: 1 | N8: 0 | S8: =SUM(L8:Q8) -> 2 | U8: 1 | V8: 1 | W8: 1 | AB8: =SUM(U8:Z8) -> 3 | AD8: =SUM(AB8,S8,J8) -> 8
A9: 2 | B9: Aliaga, Rence Carl Medeloso | C9: 1 | D9: 1 | E9: 1 | F9: 1 | J9: =SUM(C9:H9) -> 4 | L9: 1 | M9: 1 | N9: 1 | S9: =SUM(L9:Q9) -> 3 | U9: 1 | V9: 1 | W9: 1 | AB9: =SUM(U9:Z9) -> 3 | AD9: =SUM(AB9,S9,J9) -> 10
A10: 3 | B10: Almirol, Rheyjan Collado | C10: 1 | D10: 1 | E10: 1 | F10: 0 | J10: =SUM(C10:H10) -> 3 | L10: 1 | M10: 1 | N10: 1 | S10: =SUM(L10:Q10) -> 3 | U10: 1 | V10: 1 | W10: 1 | AB10: =SUM(U10:Z10) -> 3 | AD10: =SUM(AB10,S10,J10) -> 9
A11: 4 | B11: Andiano, Noel Rabago | C11: 1 | D11: 1 | E11: 1 | F11: 1 | J11: =SUM(C11:H11) -> 4 | L11: 1 | M11: 1 | N11: 1 | S11: =SUM(L11:Q11) -> 3 | U11: 1 | V11: 1 | W11: 1 | AB11: =SUM(U11:Z11) -> 3 | AD11: =SUM(AB11,S11,J11) -> 10
A12: 5 | B12: Ante, Clyde Mhyco Mendoza | C12: 1 | D12: 1 | E12: 0 | F12: 0 | J12: =SUM(C12:H12) -> 2 | L12: 0 | M12: 0 | N12: 1 | S12: =SUM(L12:Q12) -> 1 | U12: 0 | V12: 0 | W12: 0 | AB12: =SUM(U12:Z12) -> 0 | AD12: =SUM(AB12,S12,J12) -> 3
A13: 6 | B13: Antiporda, Jay Mark Cabes | C13: 1 | D13: 1 | E13: 1 | F13: 1 | J13: =SUM(C13:H13) -> 4 | L13: 1 | M13: 1 | N13: 1 | S13: =SUM(L13:Q13) -> 3 | U13: 1 | V13: 1 | W13: 1 | AB13: =SUM(U13:Z13) -> 3 | AD13: =SUM(AB13,S13,J13) -> 10
A14: 7 | B14: Aragon, Jaspher Hanly Tejada | C14: 1 | D14: 1 | E14: 0 | F14: 1 | J14: =SUM(C14:H14) -> 3 | L14: 1 | M14: 1 | N14: 1 | S14: =SUM(L14:Q14) -> 3 | U14: 0 | V14: 0 | W14: 0 | AB14: =SUM(U14:Z14) -> 0 | AD14: =SUM(AB14,S14,J14) -> 6
A15: 8 | B15: Armada, Donie Lagania | C15: 1 | D15: 1 | E15: 1 | F15: 1 | J15: =SUM(C15:H15) -> 4 | L15: 1 | M15: 1 | N15: 1 | S15: =SUM(L15:Q15) -> 3 | U15: 1 | V15: 1 | W15: 1 | AB15: =SUM(U15:Z15) -> 3 | AD15: =SUM(AB15,S15,J15) -> 10
A16: 9 | B16: Banquil, Clarissa Marie Gonzaga | C16: 1 | D16: 1 | E16: 1 | F16: 1 | J16: =SUM(C16:H16) -> 4 | L16: 1 | M16: 1 | N16: 1 | S16: =SUM(L16:Q16) -> 3 | U16: 1 | V16: 1 | W16: 1 | AB16: =SUM(U16:Z16) -> 3 | AD16: =SUM(AB16,S16,J16) -> 10
A17: 10 | B17: Bas, Disney Claire Barde | C17: 1 | D17: 1 | E17: 1 | F17: 1 | J17: =SUM(C17:H17) -> 4 | L17: 1 | M17: 1 | N17: 1 | S17: =SUM(L17:Q17) -> 3 | U17: 1 | V17: 1 | W17: 1 | AB17: =SUM(U17:Z17) -> 3 | AD17: =SUM(AB17,S17,J17) -> 10
A18: 11 | B18: Baynosa, Paul Yvanne Alinday | C18: 1 | D18: 1 | E18: 0 | F18: 1 | J18: =SUM(C18:H18) -> 3 | L18: 0 | M18: 1 | N18: 0 | S18: =SUM(L18:Q18) -> 1 | U18: 0 | V18: 0 | W18: 0 | AB18: =SUM(U18:Z18) -> 0 | AD18: =SUM(AB18,S18,J18) -> 4
A19: 12 | B19: Benig, Timothy Jade Crave | C19: 1 | D19: 1 | E19: 0 | F19: 1 | J19: =SUM(C19:H19) -> 3 | L19: 0 | M19: 1 | N19: 0 | S19: =SUM(L19:Q19) -> 1 | U19: 0 | V19: 0 | W19: 0 | AB19: =SUM(U19:Z19) -> 0 | AD19: =SUM(AB19,S19,J19) -> 4
... A52: 45 | B52: Verial, Marlou Cebuco | C52: 1 | D52: 1 | E52: 0 | F52: 1 | J52: =SUM(C52:H52) -> 3 | L52: 0 | M52: 0 | N52: 0 | S52: =SUM(L52:Q52) -> 0 | U52: 0 | V52: 0 | W52: 0 | AB52: =SUM(U52:Z52) -> 0 | AD52: =SUM(AB52,S52,J52) -> 3

Sheet Prelim
B1: =Attendance!B1 -> SUBJECT: IS 2
B2: =Attendance!B2 -> COURSE/YEAR: BSIT 1D | C2: PRELIM GRADE
B3: =Attendance!B3 -> TIME: 1:00 PM - 5:00 PM
B4: =Attendance!B4 -> ROOM: COMPLAB 4
B5: =Attendance!B5 -> UNITS: 2
C6: LECTURE | Z6: LABORATORY | AZ6: TOTAL GRADE
C7: ATTENDANCE | F7: ASSIGNMENT/SEATWORK | L7: QUIZZES | S7: EXAM | V7: PRELIM GRADE | W7: REMARKS | Z7: ATTENDANCE | AI7: LABORATORY EXERCISES | AR7: LABORATORY ASSESSMENT | AW7: PRELIM GRADE | AX7: REMARKS | AZ7: LECTURE GRADE | BA7: LAB. GRADE | BB7: PRELIM GRADE | BC7: REMARKS
C8: 0.05 | F8: 0.15 | L8: 0.3 | S8: 0.5 | Z8: 0.1 | AI8: 0.4 | AR8: 0.5
A9: No. | B9: Student Name | C9: 30 | D9: =C9/30*50+50 -> 100 | E9: =D9*0.05 -> 5 | F9: 50 | I9: =SUM(F9:H9) -> 50 | J9: =(I9/SUM($F$9:$H$9))*50+50 -> 100 | K9: =J9*0.15 -> 15 | L9: 15 | M9: 15 | P9: =SUM(L9:O9) -> 30 | Q9: =(P9/SUM($L$9:$O$9))*50+50 -> 100 | R9: =Q9*0.3 -> 30 | S9: 80 | T9: =S9/($S$9)*50+50 -> 100 | U9: =T9*0.5 -> 50 | V9: =SUM(U9,R9,K9,E9) -> 100 | Z9: 3 | AA9: 3 | AB9: 3 | AC9: 3 | AF9: =SUM(Z9:AE9) -> 12 | AG9: =(AF9/SUM($Z$9:$AE$9))*50+50 -> 100 | AH9: =AG9*0.1 -> 10 | AI9: 100 | AJ9: 100 | AO9: =SUM(AI9:AN9) -> 200 | AP9: =(AO9/SUM($AI$9:$AN$9))*50+50 -> 100 | AQ9: =AP9*0.4 -> 40 | AR9: 100 | AT9: =SUM(AR9:AS9) -> 100 | AU9: =(AT9/SUM($AR$9:$AS$9))*50+50 -> 100 | AV9: =AU9*0.5 -> 50 | AW9: =SUM(AV9,AQ9,AH9) -> 100 | AZ9: =V9*0.6 -> 60 | BA9: =AW9*0.4 -> 40 | BB9: =SUM(AZ9:BA9) -> 100 | BC9: =IF(BB9<74.5,"FAILED","PASSED") -> PASSED
A10: =Attendance!A8 -> 1 | B10: =Attendance!B8 -> Alcantara, Albert Marquez | C10: =Attendance!AD8 -> 8 | D10: =C10/30*50+50 -> 63.333333 | E10: =D10*0.05 -> 3.1666667 | F10: 50 | I10: =SUM(F10:H10) -> 50 | J10: =(I10/SUM($F$9:$H$9))*50+50 -> 100 | K10: =J10*0.15 -> 15 | L10: 14 | M10: 0 | P10: =SUM(L10:O10) -> 14 | Q10: =(P10/SUM($L$9:$O$9))*50+50 -> 73.333333 | R10: =Q10*0.3 -> 22 | S10: 74 | T10: =S10/($S$9)*50+50 -> 96.25 | U10: =T10*0.5 -> 48.125 | V10: =SUM(U10,R10,K10,E10) -> 88.291667 | W10: =IF(V10<74.5,"FAILED","PASSED") -> PASSED | Z10: 3 | AA10: 3 | AB10: 3 | AC10: 0 | AF10: =SUM(Z10:AE10) -> 9 | AG10: =(AF10/SUM($Z$9:$AE$9))*50+50 -> 87.5 | AH10: =AG10*0.1 -> 8.75 | AI10: 100 | AJ10: 0 | AO10: =SUM(AI10:AN10) -> 100 | AP10: =(AO10/SUM($AI$9:$AN$9))*50+50 -> 75 | AQ10: =AP10*0.4 -> 30 | AR10: 50 | AT10: =SUM(AR10:AS10) -> 50 | AU10: =(AT10/SUM($AR$9:$AS$9))*50+50 -> 75 | AV10: =AU10*0.5 -> 37.5 | AW10: =SUM(AV10,AQ10,AH10) -> 76.25 | AX10: =IF(AW10<74.5, "FAILED", "PASSED") -> PASSED | AZ10: =V10*0.6 -> 52.975 | BA10: =AW10*0.4 -> 30.5 | BB10: =SUM(AZ10:BA10) -> 83.475 | BC10: =IF(BB10<74.5,"FAILED","PASSED") -> PASSED
A11: =Attendance!A9 -> 2 | B11: =Attendance!B9 -> Aliaga, Rence Carl Medeloso | C11: =Attendance!AD9 -> 10 | D11: =C11/30*50+50 -> 66.666667 | E11: =D11*0.05 -> 3.3333333 | F11: 10 | I11: =SUM(F11:H11) -> 10 | J11: =(I11/SUM($F$9:$H$9))*50+50 -> 60 | K11: =J11*0.15 -> 9 | L11: 6 | M11: 14 | P11: =SUM(L11:O11) -> 20 | Q11: =(P11/SUM($L$9:$O$9))*50+50 -> 83.333333 | R11: =Q11*0.3 -> 25 | S11: 64 | T11: =S11/($S$9)*50+50 -> 90 | U11: =T11*0.5 -> 45 | V11: =SUM(U11,R11,K11,E11) -> 82.333333 | W11: =IF(V11<74.5,"FAILED","PASSED") -> PASSED | Z11: 3 | AA11: 3 | AB11: 3 | AC11: 3 | AF11: =SUM(Z11:AE11) -> 12 | AG11: =(AF11/SUM($Z$9:$AE$9))*50+50 -> 100 | AH11: =AG11*0.1 -> 10 | AI11: 100 | AJ11: 90 | AO11: =SUM(AI11:AN11) -> 190 | AP11: =(AO11/SUM($AI$9:$AN$9))*50+50 -> 97.5 | AQ11: =AP11*0.4 -> 39 | AR11: 90 | AT11: =SUM(AR11:AS11) -> 90 | AU11: =(AT11/SUM($AR$9:$AS$9))*50+50 -> 95 | AV11: =AU11*0.5 -> 47.5 | AW11: =SUM(AV11,AQ11,AH11) -> 96.5 | AX11: =IF(AW11<74.5, "FAILED", "PASSED") -> PASSED | AZ11: =V11*0.6 -> 49.4 | BA11: =AW11*0.4 -> 38.6 | BB11: =SUM(AZ11:BA11) -> 88 | BC11: =IF(BB11<74.5,"FAILED","PASSED") -> PASSED
A12: =Attendance!A10 -> 3 | B12: =Attendance!B10 -> Almirol, Rheyjan Collado | C12: =Attendance!AD10 -> 9 | D12: =C12/30*50+50 -> 65 | E12: =D12*0.05 -> 3.25 | F12: 50 | I12: =SUM(F12:H12) -> 50 | J12: =(I12/SUM($F$9:$H$9))*50+50 -> 100 | K12: =J12*0.15 -> 15 | L12: 7 | M12: 0 | P12: =SUM(L12:O12) -> 7 | Q12: =(P12/SUM($L$9:$O$9))*50+50 -> 61.666667 | R12: =Q12*0.3 -> 18.5 | S12: 51 | T12: =S12/($S$9)*50+50 -> 81.875 | U12: =T12*0.5 -> 40.9375 | V12: =SUM(U12,R12,K12,E12) -> 77.6875 | W12: =IF(V12<74.5,"FAILED","PASSED") -> PASSED | Z12: 3 | AA12: 3 | AB12: 3 | AC12: 0 | AF12: =SUM(Z12:AE12) -> 9 | AG12: =(AF12/SUM($Z$9:$AE$9))*50+50 -> 87.5 | AH12: =AG12*0.1 -> 8.75 | AI12: 100 | AJ12: 0 | AO12: =SUM(AI12:AN12) -> 100 | AP12: =(AO12/SUM($AI$9:$AN$9))*50+50 -> 75 | AQ12: =AP12*0.4 -> 30 | AR12: 50 | AT12: =SUM(AR12:AS12) -> 50 | AU12: =(AT12/SUM($AR$9:$AS$9))*50+50 -> 75 | AV12: =AU12*0.5 -> 37.5 | AW12: =SUM(AV12,AQ12,AH12) -> 76.25 | AX12: =IF(AW12<74.5, "FAILED", "PASSED") -> PASSED | AZ12: =V12*0.6 -> 46.6125 | BA12: =AW12*0.4 -> 30.5 | BB12: =SUM(AZ12:BA12) -> 77.1125 | BC12: =IF(BB12<74.5,"FAILED","PASSED") -> PASSED
A13: =Attendance!A11 -> 4 | B13: =Attendance!B11 -> Andiano, Noel Rabago | C13: =Attendance!AD11 -> 10 | D13: =C13/30*50+50 -> 66.666667 | E13: =D13*0.05 -> 3.3333333 | F13: 50 | I13: =SUM(F13:H13) -> 50 | J13: =(I13/SUM($F$9:$H$9))*50+50 -> 100 | K13: =J13*0.15 -> 15 | L13: 7 | M13: 12 | P13: =SUM(L13:O13) -> 19 | Q13: =(P13/SUM($L$9:$O$9))*50+50 -> 81.666667 | R13: =Q13*0.3 -> 24.5 | S13: 38 | T13: =S13/($S$9)*50+50 -> 73.75 | U13: =T13*0.5 -> 36.875 | V13: =SUM(U13,R13,K13,E13) -> 79.708333 | W13: =IF(V13<74.5,"FAILED","PASSED") -> PASSED | Z13: 3 | AA13: 3 | AB13: 3 | AC13: 3 | AF13: =SUM(Z13:AE13) -> 12 | AG13: =(AF13/SUM($Z$9:$AE$9))*50+50 -> 100 | AH13: =AG13*0.1 -> 10 | AI13: 100 | AJ13: 80 | AO13: =SUM(AI13:AN13) -> 180 | AP13: =(AO13/SUM($AI$9:$AN$9))*50+50 -> 95 | AQ13: =AP13*0.4 -> 38 | AR13: 90 | AT13: =SUM(AR13:AS13) -> 90 | AU13: =(AT13/SUM($AR$9:$AS$9))*50+50 -> 95 | AV13: =AU13*0.5 -> 47.5 | AW13: =SUM(AV13,AQ13,AH13) -> 95.5 | AX13: =IF(AW13<74.5, "FAILED", "PASSED") -> PASSED | AZ13: =V13*0.6 -> 47.825 | BA13: =AW13*0.4 -> 38.2 | BB13: =SUM(AZ13:BA13) -> 86.025 | BC13: =IF(BB13<74.5,"FAILED","PASSED") -> PASSED
A14: =Attendance!A12 -> 5 | B14: =Attendance!B12 -> Ante, Clyde Mhyco Mendoza | C14: =Attendance!AD12 -> 3 | D14: =C14/30*50+50 -> 55 | E14: =D14*0.05 -> 2.75 | F14: 10 | I14: =SUM(F14:H14) -> 10 | J14: =(I14/SUM($F$9:$H$9))*50+50 -> 60 | K14: =J14*0.15 -> 9 | L14: 0 | M14: 0 | P14: =SUM(L14:O14) -> 0 | Q14: =(P14/SUM($L$9:$O$9))*50+50 -> 50 | R14: =Q14*0.3 -> 15 | S14: 66 | T14: =S14/($S$9)*50+50 -> 91.25 | U14: =T14*0.5 -> 45.625 | V14: =SUM(U14,R14,K14,E14) -> 72.375 | W14: =IF(V14<74.5,"FAILED","PASSED") -> FAILED | Z14: 3 | AA14: 3 | AB14: 0 | AC14: 0 | AF14: =SUM(Z14:AE14) -> 6 | AG14: =(AF14/SUM($Z$9:$AE$9))*50+50 -> 75 | AH14: =AG14*0.1 -> 7.5 | AI14: 100 | AJ14: 85 | AO14: =SUM(AI14:AN14) -> 185 | AP14: =(AO14/SUM($AI$9:$AN$9))*50+50 -> 96.25 | AQ14: =AP14*0.4 -> 38.5 | AR14: 50 | AT14: =SUM(AR14:AS14) -> 50 | AU14: =(AT14/SUM($AR$9:$AS$9))*50+50 -> 75 | AV14: =AU14*0.5 -> 37.5 | AW14: =SUM(AV14,AQ14,AH14) -> 83.5 | AX14: =IF(AW14<74.5, "FAILED", "PASSED") -> PASSED | AZ14: =V14*0.6 -> 43.425 | BA14: =AW14*0.4 -> 33.4 | BB14: =SUM(AZ14:BA14) -> 76.825 | BC14: =IF(BB14<74.5,"FAILED","PASSED") -> PASSED
A15: =Attendance!A13 -> 6 | B15: =Attendance!B13 -> Antiporda, Jay Mark Cabes | C15: =Attendance!AD13 -> 10 | D15: =C15/30*50+50 -> 66.666667 | E15: =D15*0.05 -> 3.3333333 | F15: 50 | I15: =SUM(F15:H15) -> 50 | J15: =(I15/SUM($F$9:$H$9))*50+50 -> 100 | K15: =J15*0.15 -> 15 | L15: 11 | M15: 14 | P15: =SUM(L15:O15) -> 25 | Q15: =(P15/SUM($L$9:$O$9))*50+50 -> 91.666667 | R15: =Q15*0.3 -> 27.5 | S15: 54 | T15: =S15/($S$9)*50+50 -> 83.75 | U15: =T15*0.5 -> 41.875 | V15: =SUM(U15,R15,K15,E15) -> 87.708333 | W15: =IF(V15<74.5,"FAILED","PASSED") -> PASSED | Z15: 3 | AA15: 3 | AB15: 3 | AC15: 3 | AF15: =SUM(Z15:AE15) -> 12 | AG15: =(AF15/SUM($Z$9:$AE$9))*50+50 -> 100 | AH15: =AG15*0.1 -> 10 | AI15: 100 | AJ15: 100 | AO15: =SUM(AI15:AN15) -> 200 | AP15: =(AO15/SUM($AI$9:$AN$9))*50+50 -> 100 | AQ15: =AP15*0.4 -> 40 | AR15: 90 | AT15: =SUM(AR15:AS15) -> 90 | AU15: =(AT15/SUM($AR$9:$AS$9))*50+50 -> 95 | AV15: =AU15*0.5 -> 47.5 | AW15: =SUM(AV15,AQ15,AH15) -> 97.5 | AX15: =IF(AW15<74.5, "FAILED", "PASSED") -> PASSED | AZ15: =V15*0.6 -> 52.625 | BA15: =AW15*0.4 -> 39 | BB15: =SUM(AZ15:BA15) -> 91.625 | BC15: =IF(BB15<74.5,"FAILED","PASSED") -> PASSED
A16: =Attendance!A14 -> 7 | B16: =Attendance!B14 -> Aragon, Jaspher Hanly Tejada | C16: =Attendance!AD14 -> 6 | D16: =C16/30*50+50 -> 60 | E16: =D16*0.05 -> 3 | F16: 50 | I16: =SUM(F16:H16) -> 50 | J16: =(I16/SUM($F$9:$H$9))*50+50 -> 100 | K16: =J16*0.15 -> 15 | L16: 0 | M16: 11 | P16: =SUM(L16:O16) -> 11 | Q16: =(P16/SUM($L$9:$O$9))*50+50 -> 68.333333 | R16: =Q16*0.3 -> 20.5 | S16: 77 | T16: =S16/($S$9)*50+50 -> 98.125 | U16: =T16*0.5 -> 49.0625 | V16: =SUM(U16,R16,K16,E16) -> 87.5625 | W16: =IF(V16<74.5,"FAILED","PASSED") -> PASSED | Z16: 3 | AA16: 3 | AB16: 0 | AC16: 3 | AF16: =SUM(Z16:AE16) -> 9 | AG16: =(AF16/SUM($Z$9:$AE$9))*50+50 -> 87.5 | AH16: =AG16*0.1 -> 8.75 | AI16: 95 | AJ16: 100 | AO16: =SUM(AI16:AN16) -> 195 | AP16: =(AO16/SUM($AI$9:$AN$9))*50+50 -> 98.75 | AQ16: =AP16*0.4 -> 39.5 | AR16: 90 | AT16: =SUM(AR16:AS16) -> 90 | AU16: =(AT16/SUM($AR$9:$AS$9))*50+50 -> 95 | AV16: =AU16*0.5 -> 47.5 | AW16: =SUM(AV16,AQ16,AH16) -> 95.75 | AX16: =IF(AW16<74.5, "FAILED", "PASSED") -> PASSED | AZ16: =V16*0.6 -> 52.5375 | BA16: =AW16*0.4 -> 38.3 | BB16: =SUM(AZ16:BA16) -> 90.8375 | BC16: =IF(BB16<74.5,"FAILED","PASSED") -> PASSED
A17: =Attendance!A15 -> 8 | B17: =Attendance!B15 -> Armada, Donie Lagania | C17: =Attendance!AD15 -> 10 | D17: =C17/30*50+50 -> 66.666667 | E17: =D17*0.05 -> 3.3333333 | F17: 50 | I17: =SUM(F17:H17) -> 50 | J17: =(I17/SUM($F$9:$H$9))*50+50 -> 100 | K17: =J17*0.15 -> 15 | L17: 10 | M17: 14 | P17: =SUM(L17:O17) -> 24 | Q17: =(P17/SUM($L$9:$O$9))*50+50 -> 90 | R17: =Q17*0.3 -> 27 | S17: 75 | T17: =S17/($S$9)*50+50 -> 96.875 | U17: =T17*0.5 -> 48.4375 | V17: =SUM(U17,R17,K17,E17) -> 93.770833 | W17: =IF(V17<74.5,"FAILED","PASSED") -> PASSED | Z17: 3 | AA17: 3 | AB17: 3 | AC17: 3 | AF17: =SUM(Z17:AE17) -> 12 | AG17: =(AF17/SUM($Z$9:$AE$9))*50+50 -> 100 | AH17: =AG17*0.1 -> 10 | AI17: 100 | AJ17: 75 | AO17: =SUM(AI17:AN17) -> 175 | AP17: =(AO17/SUM($AI$9:$AN$9))*50+50 -> 93.75 | AQ17: =AP17*0.4 -> 37.5 | AR17: 90 | AT17: =SUM(AR17:AS17) -> 90 | AU17: =(AT17/SUM($AR$9:$AS$9))*50+50 -> 95 | AV17: =AU17*0.5 -> 47.5 | AW17: =SUM(AV17,AQ17,AH17) -> 95 | AX17: =IF(AW17<74.5, "FAILED", "PASSED") -> PASSED | AZ17: =V17*0.6 -> 56.2625 | BA17: =AW17*0.4 -> 38 | BB17: =SUM(AZ17:BA17) -> 94.2625 | BC17: =IF(BB17<74.5,"FAILED","PASSED") -> PASSED
A18: =Attendance!A16 -> 9 | B18: =Attendance!B16 -> Banquil, Clarissa Marie Gonzaga | C18: =Attendance!AD16 -> 10 | D18: =C18/30*50+50 -> 66.666667 | E18: =D18*0.05 -> 3.3333333 | F18: 50 | I18: =SUM(F18:H18) -> 50 | J18: =(I18/SUM($F$9:$H$9))*50+50 -> 100 | K18: =J18*0.15 -> 15 | L18: 15 | M18: 13 | P18: =SUM(L18:O18) -> 28 | Q18: =(P18/SUM($L$9:$O$9))*50+50 -> 96.666667 | R18: =Q18*0.3 -> 29 | S18: 62 | T18: =S18/($S$9)*50+50 -> 88.75 | U18: =T18*0.5 -> 44.375 | V18: =SUM(U18,R18,K18,E18) -> 91.708333 | W18: =IF(V18<74.5,"FAILED","PASSED") -> PASSED | Z18: 3 | AA18: 3 | AB18: 3 | AC18: 3 | AF18: =SUM(Z18:AE18) -> 12 | AG18: =(AF18/SUM($Z$9:$AE$9))*50+50 -> 100 | AH18: =AG18*0.1 -> 10 | AI18: 100 | AJ18: 100 | AO18: =SUM(AI18:AN18) -> 200 | AP18: =(AO18/SUM($AI$9:$AN$9))*50+50 -> 100 | AQ18: =AP18*0.4 -> 40 | AR18: 90 | AT18: =SUM(AR18:AS18) -> 90 | AU18: =(AT18/SUM($AR$9:$AS$9))*50+50 -> 95 | AV18: =AU18*0.5 -> 47.5 | AW18: =SUM(AV18,AQ18,AH18) -> 97.5 | AX18: =IF(AW18<74.5, "FAILED", "PASSED") -> PASSED | AZ18: =V18*0.6 -> 55.025 | BA18: =AW18*0.4 -> 39 | BB18: =SUM(AZ18:BA18) -> 94.025 | BC18: =IF(BB18<74.5,"FAILED","PASSED") -> PASSED
A19: =Attendance!A17 -> 10 | B19: =Attendance!B17 -> Bas, Disney Claire Barde | C19: =Attendance!AD17 -> 10 | D19: =C19/30*50+50 -> 66.666667 | E19: =D19*0.05 -> 3.3333333 | F19: 50 | I19: =SUM(F19:H19) -> 50 | J19: =(I19/SUM($F$9:$H$9))*50+50 -> 100 | K19: =J19*0.15 -> 15 | L19: 14 | M19: 14 | P19: =SUM(L19:O19) -> 28 | Q19: =(P19/SUM($L$9:$O$9))*50+50 -> 96.666667 | R19: =Q19*0.3 -> 29 | S19: 73 | T19: =S19/($S$9)*50+50 -> 95.625 | U19: =T19*0.5 -> 47.8125 | V19: =SUM(U19,R19,K19,E19) -> 95.145833 | W19: =IF(V19<74.5,"FAILED","PASSED") -> PASSED | Z19: 3 | AA19: 3 | AB19: 3 | AC19: 3 | AF19: =SUM(Z19:AE19) -> 12 | AG19: =(AF19/SUM($Z$9:$AE$9))*50+50 -> 100 | AH19: =AG19*0.1 -> 10 | AI19: 100 | AJ19: 95 | AO19: =SUM(AI19:AN19) -> 195 | AP19: =(AO19/SUM($AI$9:$AN$9))*50+50 -> 98.75 | AQ19: =AP19*0.4 -> 39.5 | AR19: 90 | AT19: =SUM(AR19:AS19) -> 90 | AU19: =(AT19/SUM($AR$9:$AS$9))*50+50 -> 95 | AV19: =AU19*0.5 -> 47.5 | AW19: =SUM(AV19,AQ19,AH19) -> 97 | AX19: =IF(AW19<74.5, "FAILED", "PASSED") -> PASSED | AZ19: =V19*0.6 -> 57.0875 | BA19: =AW19*0.4 -> 38.8 | BB19: =SUM(AZ19:BA19) -> 95.8875 | BC19: =IF(BB19<74.5,"FAILED","PASSED") -> PASSED
A20: =Attendance!A18 -> 11 | B20: =Attendance!B18 -> Baynosa, Paul Yvanne Alinday | C20: =Attendance!AD18 -> 4 | D20: =C20/30*50+50 -> 56.666667 | E20: =D20*0.05 -> 2.8333333 | F20: 50 | I20: =SUM(F20:H20) -> 50 | J20: =(I20/SUM($F$9:$H$9))*50+50 -> 100 | K20: =J20*0.15 -> 15 | L20: 0 | M20: 12 | P20: =SUM(L20:O20) -> 12 | Q20: =(P20/SUM($L$9:$O$9))*50+50 -> 70 | R20: =Q20*0.3 -> 21 | S20: 70 | T20: =S20/($S$9)*50+50 -> 93.75 | U20: =T20*0.5 -> 46.875 | V20: =SUM(U20,R20,K20,E20) -> 85.708333 | W20: =IF(V20<74.5,"FAILED","PASSED") -> PASSED | Z20: 3 | AA20: 3 | AB20: 0 | AC20: 3 | AF20: =SUM(Z20:AE20) -> 9 | AG20: =(AF20/SUM($Z$9:$AE$9))*50+50 -> 87.5 | AH20: =AG20*0.1 -> 8.75 | AI20: 90 | AJ20: 100 | AO20: =SUM(AI20:AN20) -> 190 | AP20: =(AO20/SUM($AI$9:$AN$9))*50+50 -> 97.5 | AQ20: =AP20*0.4 -> 39 | AR20: 90 | AT20: =SUM(AR20:AS20) -> 90 | AU20: =(AT20/SUM($AR$9:$AS$9))*50+50 -> 95 | AV20: =AU20*0.5 -> 47.5 | AW20: =SUM(AV20,AQ20,AH20) -> 95.25 | AX20: =IF(AW20<74.5, "FAILED", "PASSED") -> PASSED | AZ20: =V20*0.6 -> 51.425 | BA20: =AW20*0.4 -> 38.1 | BB20: =SUM(AZ20:BA20) -> 89.525 | BC20: =IF(BB20<74.5,"FAILED","PASSED") -> PASSED
A21: =Attendance!A19 -> 12 | B21: =Attendance!B19 -> Benig, Timothy Jade Crave | C21: =Attendance!AD19 -> 4 | D21: =C21/30*50+50 -> 56.666667 | E21: =D21*0.05 -> 2.8333333 | F21: 50 | I21: =SUM(F21:H21) -> 50 | J21: =(I21/SUM($F$9:$H$9))*50+50 -> 100 | K21: =J21*0.15 -> 15 | L21: 0 | M21: 13 | P21: =SUM(L21:O21) -> 13 | Q21: =(P21/SUM($L$9:$O$9))*50+50 -> 71.666667 | R21: =Q21*0.3 -> 21.5 | S21: 75 | T21: =S21/($S$9)*50+50 -> 96.875 | U21: =T21*0.5 -> 48.4375 | V21: =SUM(U21,R21,K21,E21) -> 87.770833 | W21: =IF(V21<74.5,"FAILED","PASSED") -> PASSED | Z21: 3 | AA21: 3 | AB21: 0 | AC21: 3 | AF21: =SUM(Z21:AE21) -> 9 | AG21: =(AF21/SUM($Z$9:$AE$9))*50+50 -> 87.5 | AH21: =AG21*0.1 -> 8.75 | AI21: 100 | AJ21: 80 | AO21: =SUM(AI21:AN21) -> 180 | AP21: =(AO21/SUM($AI$9:$AN$9))*50+50 -> 95 | AQ21: =AP21*0.4 -> 38 | AR21: 90 | AT21: =SUM(AR21:AS21) -> 90 | AU21: =(AT21/SUM($AR$9:$AS$9))*50+50 -> 95 | AV21: =AU21*0.5 -> 47.5 | AW21: =SUM(AV21,AQ21,AH21) -> 94.25 | AX21: =IF(AW21<74.5, "FAILED", "PASSED") -> PASSED | AZ21: =V21*0.6 -> 52.6625 | BA21: =AW21*0.4 -> 37.7 | BB21: =SUM(AZ21:BA21) -> 90.3625 | BC21: =IF(BB21<74.5,"FAILED","PASSED") -> PASSED
... A54: =Attendance!A52 -> 45 | B54: =Attendance!B52 -> Verial, Marlou Cebuco | C54: =Attendance!AD52 -> 3 | D54: =C54/30*50+50 -> 55 | E54: =D54*0.05 -> 2.75 | F54: 50 | I54: =SUM(F54:H54) -> 50 | J54: =(I54/SUM($F$9:$H$9))*50+50 -> 100 | K54: =J54*0.15 -> 15 | L54: 0 | M54: 13 | P54: =SUM(L54:O54) -> 13 | Q54: =(P54/SUM($L$9:$O$9))*50+50 -> 71.666667 | R54: =Q54*0.3 -> 21.5 | S54: 54 | T54: =S54/($S$9)*50+50 -> 83.75 | U54: =T54*0.5 -> 41.875 | V54: =SUM(U54,R54,K54,E54) -> 81.125 | W54: =IF(V54<74.5,"FAILED","PASSED") -> PASSED | Z54: 3 | AA54: 3 | AB54: 0 | AC54: 3 | AF54: =SUM(Z54:AE54) -> 9 | AG54: =(AF54/SUM($Z$9:$AE$9))*50+50 -> 87.5 | AH54: =AG54*0.1 -> 8.75 | AI54: 80 | AJ54: 95 | AO54: =SUM(AI54:AN54) -> 175 | AP54: =(AO54/SUM($AI$9:$AN$9))*50+50 -> 93.75 | AQ54: =AP54*0.4 -> 37.5 | AR54: 90 | AT54: =SUM(AR54:AS54) -> 90 | AU54: =(AT54/SUM($AR$9:$AS$9))*50+50 -> 95 | AV54: =AU54*0.5 -> 47.5 | AW54: =SUM(AV54,AQ54,AH54) -> 93.75 | AX54: =IF(AW54<74.5, "FAILED", "PASSED") -> PASSED | AZ54: =V54*0.6 -> 48.675 | BA54: =AW54*0.4 -> 37.5 | BB54: =SUM(AZ54:BA54) -> 86.175 | BC54: =IF(BB54<74.5,"FAILED","PASSED") -> PASSED

Sheet Midterm
B1: =Attendance!B1 -> SUBJECT: IS 2
B2: =Attendance!B2 -> COURSE/YEAR: BSIT 1D | C2: MIDTERM GRADE
B3: =Attendance!B3 -> TIME: 1:00 PM - 5:00 PM
B4: =Attendance!B4 -> ROOM: COMPLAB 4
B5: =Attendance!B5 -> UNITS: 2
C6: LECTURE | Z6: LABORATORY | AZ6: TOTAL GRADE
C7: ATTENDANCE | F7: ASSIGNMENT/SEATWORK | L7: QUIZZES | S7: EXAM | V7: PRELIM GRADE | W7: REMARKS | Z7: ATTENDANCE | AI7: LABORATORY EXERCISES | AR7: LABORATORY ASSESSMENT | AW7: PRELIM GRADE | AX7: REMARKS | AZ7: LECTURE GRADE | BA7: LAB. GRADE | BB7: PRELIM GRADE | BC7: REMARKS
C8: 0.05 | F8: 0.15 | L8: 0.3 | S8: 0.5 | Z8: 0.1 | AI8: 0.4 | AR8: 0.5
A9: No. | B9: Student Name | C9: 3 | D9: =C9/3*50+50 -> 100 | E9: =D9*0.05 -> 5 | F9: 50 | I9: =SUM(F9:H9) -> 50 | J9: =(I9/SUM($F$9:$H$9))*50+50 -> 100 | K9: =J9*0.15 -> 15 | L9: 15 | M9: 10 | N9: 50 | P9: =SUM(L9:O9) -> 75 | Q9: =(P9/SUM($L$9:$O$9))*50+50 -> 100 | R9: =Q9*0.3 -> 30 | S9: 80 | T9: =S9/($S$9)*50+50 -> 100 | U9: =T9*0.5 -> 50 | V9: =SUM(U9,R9,K9,E9) -> 100 | Z9: 3 | AA9: 3 | AB9: 3 | AF9: =SUM(Z9:AE9) -> 9 | AG9: =(AF9/SUM($Z$9:$AE$9))*50+50 -> 100 | AH9: =AG9*0.1 -> 10 | AI9: 100 | AJ9: 100 | AO9: =SUM(AI9:AN9) -> 200 | AP9: =(AO9/SUM($AI$9:$AN$9))*50+50 -> 100 | AQ9: =AP9*0.4 -> 40 | AR9: 100 | AT9: =SUM(AR9:AS9) -> 100 | AU9: =(AT9/SUM($AR$9:$AS$9))*50+50 -> 100 | AV9: =AU9*0.5 -> 50 | AW9: =SUM(AV9,AQ9,AH9) -> 100 | AZ9: =V9*0.6 -> 60 | BA9: =AW9*0.4 -> 40 | BB9: =SUM(AZ9:BA9) -> 100 | BC9: =IF(BB9<74.5,"FAILED","PASSED") -> PASSED
A10: =Attendance!A8 -> 1 | B10: =Attendance!B8 -> Alcantara, Albert Marquez | C10: =Attendance!S8 -> 2 | D10: =C10/3*50+50 -> 83.333333 | E10: =D10*0.05 -> 4.1666667 | F10: 40 | I10: =SUM(F10:H10) -> 40 | J10: =(I10/SUM($F$9:$H$9))*50+50 -> 90 | K10: =J10*0.15 -> 13.5 | L10: 13 | M10: 0 | N10: 44 | P10: =SUM(L10:O10) -> 57 | Q10: =(P10/SUM($L$9:$O$9))*50+50 -> 88 | R10: =Q10*0.3 -> 26.4 | S10: 68 | T10: =S10/($S$9)*50+50 -> 92.5 | U10: =T10*0.5 -> 46.25 | V10: =SUM(U10,R10,K10,E10) -> 90.316667 | W10: =IF(V10<74.5,"FAILED","PASSED") -> PASSED | Z10: 3 | AA10: 3 | AB10: 0 | AF10: =SUM(Z10:AE10) -> 6 | AG10: =(AF10/SUM($Z$9:$AE$9))*50+50 -> 83.333333 | AH10: =AG10*0.1 -> 8.3333333 | AI10: 85 | AJ10: 0 | AO10: =SUM(AI10:AN10) -> 85 | AP10: =(AO10/SUM($AI$9:$AN$9))*50+50 -> 71.25 | AQ10: =AP10*0.4 -> 28.5 | AR10: 83 | AT10: =SUM(AR10:AS10) -> 83 | AU10: =(AT10/SUM($AR$9:$AS$9))*50+50 -> 91.5 | AV10: =AU10*0.5 -> 45.75 | AW10: =SUM(AV10,AQ10,AH10) -> 82.583333 | AX10: =IF(AW10<74.5, "FAILED", "PASSED") -> PASSED | AZ10: =V10*0.6 -> 54.19 | BA10: =AW10*0.4 -> 33.033333 | BB10: =SUM(AZ10:BA10) -> 87.223333 | BC10: =IF(BB10<74.5,"FAILED","PASSED") -> PASSED
A11: =Attendance!A9 -> 2 | B11: =Attendance!B9 -> Aliaga, Rence Carl Medeloso | C11: =Attendance!S9 -> 3 | D11: =C11/3*50+50 -> 100 | E11: =D11*0.05 -> 5 | F11: 40 | I11: =SUM(F11:H11) -> 40 | J11: =(I11/SUM($F$9:$H$9))*50+50 -> 90 | K11: =J11*0.15 -> 13.5 | L11: 6 | M11: 9 | N11: 37 | P11: =SUM(L11:O11) -> 52 | Q11: =(P11/SUM($L$9:$O$9))*50+50 -> 84.666667 | R11: =Q11*0.3 -> 25.4 | S11: 58 | T11: =S11/($S$9)*50+50 -> 86.25 | U11: =T11*0.5 -> 43.125 | V11: =SUM(U11,R11,K11,E11) -> 87.025 | W11: =IF(V11<74.5,"FAILED","PASSED") -> PASSED | Z11: 3 | AA11: 3 | AB11: 0 | AF11: =SUM(Z11:AE11) -> 6 | AG11: =(AF11/SUM($Z$9:$AE$9))*50+50 -> 83.333333 | AH11: =AG11*0.1 -> 8.3333333 | AI11: 75 | AJ11: 0 | AO11: =SUM(AI11:AN11) -> 75 | AP11: =(AO11/SUM($AI$9:$AN$9))*50+50 -> 68.75 | AQ11: =AP11*0.4 -> 27.5 | AR11: 91 | AT11: =SUM(AR11:AS11) -> 91 | AU11: =(AT11/SUM($AR$9:$AS$9))*50+50 -> 95.5 | AV11: =AU11*0.5 -> 47.75 | AW11: =SUM(AV11,AQ11,AH11) -> 83.583333 | AX11: =IF(AW11<74.5, "FAILED", "PASSED") -> PASSED | AZ11: =V11*0.6 -> 52.215 | BA11: =AW11*0.4 -> 33.433333 | BB11: =SUM(AZ11:BA11) -> 85.648333 | BC11: =IF(BB11<74.5,"FAILED","PASSED") -> PASSED
A12: =Attendance!A10 -> 3 | B12: =Attendance!B10 -> Almirol, Rheyjan Collado | C12: =Attendance!S10 -> 3 | D12: =C12/3*50+50 -> 100 | E12: =D12*0.05 -> 5 | F12: 40 | I12: =SUM(F12:H12) -> 40 | J12: =(I12/SUM($F$9:$H$9))*50+50 -> 90 | K12: =J12*0.15 -> 13.5 | L12: 7 | M12: 9 | N12: 41 | P12: =SUM(L12:O12) -> 57 | Q12: =(P12/SUM($L$9:$O$9))*50+50 -> 88 | R12: =Q12*0.3 -> 26.4 | S12: 52 | T12: =S12/($S$9)*50+50 -> 82.5 | U12: =T12*0.5 -> 41.25 | V12: =SUM(U12,R12,K12,E12) -> 86.15 | W12: =IF(V12<74.5,"FAILED","PASSED") -> PASSED | Z12: 3 | AA12: 3 | AB12: 3 | AF12: =SUM(Z12:AE12) -> 9 | AG12: =(AF12/SUM($Z$9:$AE$9))*50+50 -> 100 | AH12: =AG12*0.1 -> 10 | AI12: 85 | AJ12: 85 | AO12: =SUM(AI12:AN12) -> 170 | AP12: =(AO12/SUM($AI$9:$AN$9))*50+50 -> 92.5 | AQ12: =AP12*0.4 -> 37 | AR12: 91 | AT12: =SUM(AR12:AS12) -> 91 | AU12: =(AT12/SUM($AR$9:$AS$9))*50+50 -> 95.5 | AV12: =AU12*0.5 -> 47.75 | AW12: =SUM(AV12,AQ12,AH12) -> 94.75 | AX12: =IF(AW12<74.5, "FAILED", "PASSED") -> PASSED | AZ12: =V12*0.6 -> 51.69 | BA12: =AW12*0.4 -> 37.9 | BB12: =SUM(AZ12:BA12) -> 89.59 | BC12: =IF(BB12<74.5,"FAILED","PASSED") -> PASSED
A13: =Attendance!A11 -> 4 | B13: =Attendance!B11 -> Andiano, Noel Rabago | C13: =Attendance!S11 -> 3 | D13: =C13/3*50+50 -> 100 | E13: =D13*0.05 -> 5 | F13: 40 | I13: =SUM(F13:H13) -> 40 | J13: =(I13/SUM($F$9:$H$9))*50+50 -> 90 | K13: =J13*0.15 -> 13.5 | L13: 4 | M13: 1 | N13: 34 | P13: =SUM(L13:O13) -> 39 | Q13: =(P13/SUM($L$9:$O$9))*50+50 -> 76 | R13: =Q13*0.3 -> 22.8 | S13: 33 | T13: =S13/($S$9)*50+50 -> 70.625 | U13: =T13*0.5 -> 35.3125 | V13: =SUM(U13,R13,K13,E13) -> 76.6125 | W13: =IF(V13<74.5,"FAILED","PASSED") -> PASSED | Z13: 3 | AA13: 3 | AB13: 0 | AF13: =SUM(Z13:AE13) -> 6 | AG13: =(AF13/SUM($Z$9:$AE$9))*50+50 -> 83.333333 | AH13: =AG13*0.1 -> 8.3333333 | AI13: 86 | AJ13: 88 | AO13: =SUM(AI13:AN13) -> 174 | AP13: =(AO13/SUM($AI$9:$AN$9))*50+50 -> 93.5 | AQ13: =AP13*0.4 -> 37.4 | AR13: 84 | AT13: =SUM(AR13:AS13) -> 84 | AU13: =(AT13/SUM($AR$9:$AS$9))*50+50 -> 92 | AV13: =AU13*0.5 -> 46 | AW13: =SUM(AV13,AQ13,AH13) -> 91.733333 | AX13: =IF(AW13<74.5, "FAILED", "PASSED") -> PASSED | AZ13: =V13*0.6 -> 45.9675 | BA13: =AW13*0.4 -> 36.693333 | BB13: =SUM(AZ13:BA13) -> 82.660833 | BC13: =IF(BB13<74.5,"FAILED","PASSED") -> PASSED
A14: =Attendance!A12 -> 5 | B14: =Attendance!B12 -> Ante, Clyde Mhyco Mendoza | C14: =Attendance!S12 -> 1 | D14: =C14/3*50+50 -> 66.666667 | E14: =D14*0.05 -> 3.3333333 | F14: 40 | I14: =SUM(F14:H14) -> 40 | J14: =(I14/SUM($F$9:$H$9))*50+50 -> 90 | K14: =J14*0.15 -> 13.5 | L14: 0 | M14: 5 | N14: 0 | P14: =SUM(L14:O14) -> 5 | Q14: =(P14/SUM($L$9:$O$9))*50+50 -> 53.333333 | R14: =Q14*0.3 -> 16 | S14: 31 | T14: =S14/($S$9)*50+50 -> 69.375 | U14: =T14*0.5 -> 34.6875 | V14: =SUM(U14,R14,K14,E14) -> 67.520833 | W14: =IF(V14<74.5,"FAILED","PASSED") -> FAILED | Z14: 0 | AA14: 0 | AB14: 3 | AF14: =SUM(Z14:AE14) -> 3 | AG14: =(AF14/SUM($Z$9:$AE$9))*50+50 -> 66.666667 | AH14: =AG14*0.1 -> 6.6666667 | AI14: 85 | AJ14: 85 | AO14: =SUM(AI14:AN14) -> 170 | AP14: =(AO14/SUM($AI$9:$AN$9))*50+50 -> 92.5 | AQ14: =AP14*0.4 -> 37 | AR14: 0 | AT14: =SUM(AR14:AS14) -> 0 | AU14: =(AT14/SUM($AR$9:$AS$9))*50+50 -> 50 | AV14: =AU14*0.5 -> 25 | AW14: =SUM(AV14,AQ14,AH14) -> 68.666667 | AX14: =IF(AW14<74.5, "FAILED", "PASSED") -> FAILED | AZ14: =V14*0.6 -> 40.5125 | BA14: =AW14*0.4 -> 27.466667 | BB14: =SUM(AZ14:BA14) -> 67.979167 | BC14: =IF(BB14<74.5,"FAILED","PASSED") -> FAILED
A15: =Attendance!A13 -> 6 | B15: =Attendance!B13 -> Antiporda, Jay Mark Cabes | C15: =Attendance!S13 -> 3 | D15: =C15/3*50+50 -> 100 | E15: =D15*0.05 -> 5 | F15: 40 | I15: =SUM(F15:H15) -> 40 | J15: =(I15/SUM($F$9:$H$9))*50+50 -> 90 | K15: =J15*0.15 -> 13.5 | L15: 10 | M15: 9 | N15: 29 | P15: =SUM(L15:O15) -> 48 | Q15: =(P15/SUM($L$9:$O$9))*50+50 -> 82 | R15: =Q15*0.3 -> 24.6 | S15: 58 | T15: =S15/($S$9)*50+50 -> 86.25 | U15: =T15*0.5 -> 43.125 | V15: =SUM(U15,R15,K15,E15) -> 86.225 | W15: =IF(V15<74.5,"FAILED","PASSED") -> PASSED | Z15: 3 | AA15: 3 | AB15: 3 | AF15: =SUM(Z15:AE15) -> 9 | AG15: =(AF15/SUM($Z$9:$AE$9))*50+50 -> 100 | AH15: =AG15*0.1 -> 10 | AI15: 75 | AJ15: 88 | AO15: =SUM(AI15:AN15) -> 163 | AP15: =(AO15/SUM($AI$9:$AN$9))*50+50 -> 90.75 | AQ15: =AP15*0.4 -> 36.3 | AR15: 89 | AT15: =SUM(AR15:AS15) -> 89 | AU15: =(AT15/SUM($AR$9:$AS$9))*50+50 -> 94.5 | AV15: =AU15*0.5 -> 47.25 | AW15: =SUM(AV15,AQ15,AH15) -> 93.55 | AX15: =IF(AW15<74.5, "FAILED", "PASSED") -> PASSED | AZ15: =V15*0.6 -> 51.735 | BA15: =AW15*0.4 -> 37.42 | BB15: =SUM(AZ15:BA15) -> 89.155 | BC15: =IF(BB15<74.5,"FAILED","PASSED") -> PASSED
A16: =Attendance!A14 -> 7 | B16: =Attendance!B14 -> Aragon, Jaspher Hanly Tejada | C16: =Attendance!S14 -> 3 | D16: =C16/3*50+50 -> 100 | E16: =D16*0.05 -> 5 | F16: 40 | I16: =SUM(F16:H16) -> 40 | J16: =(I16/SUM($F$9:$H$9))*50+50 -> 90 | K16: =J16*0.15 -> 13.5 | L16: 7 | M16: 8 | N16: 41 | P16: =SUM(L16:O16) -> 56 | Q16: =(P16/SUM($L$9:$O$9))*50+50 -> 87.333333 | R16: =Q16*0.3 -> 26.2 | S16: 68 | T16: =S16/($S$9)*50+50 -> 92.5 | U16: =T16*0.5 -> 46.25 | V16: =SUM(U16,R16,K16,E16) -> 90.95 | W16: =IF(V16<74.5,"FAILED","PASSED") -> PASSED | Z16: 3 | AA16: 3 | AB16: 3 | AF16: =SUM(Z16:AE16) -> 9 | AG16: =(AF16/SUM($Z$9:$AE$9))*50+50 -> 100 | AH16: =AG16*0.1 -> 10 | AI16: 75 | AJ16: 75 | AO16: =SUM(AI16:AN16) -> 150 | AP16: =(AO16/SUM($AI$9:$AN$9))*50+50 -> 87.5 | AQ16: =AP16*0.4 -> 35 | AR16: 89 | AT16: =SUM(AR16:AS16) -> 89 | AU16: =(AT16/SUM($AR$9:$AS$9))*50+50 -> 94.5 | AV16: =AU16*0.5 -> 47.25 | AW16: =SUM(AV16,AQ16,AH16) -> 92.25 | AX16: =IF(AW16<74.5, "FAILED", "PASSED") -> PASSED | AZ16: =V16*0.6 -> 54.57 | BA16: =AW16*0.4 -> 36.9 | BB16: =SUM(AZ16:BA16) -> 91.47 | BC16: =IF(BB16<74.5,"FAILED","PASSED") -> PASSED
A17: =Attendance!A15 -> 8 | B17: =Attendance!B15 -> Armada, Donie Lagania | C17: =Attendance!S15 -> 3 | D17: =C17/3*50+50 -> 100 | E17: =D17*0.05 -> 5 | F17: 40 | I17: =SUM(F17:H17) -> 40 | J17: =(I17/SUM($F$9:$H$9))*50+50 -> 90 | K17: =J17*0.15 -> 13.5 | L17: 14 | M17: 9 | N17: 45 | P17: =SUM(L17:O17) -> 68 | Q17: =(P17/SUM($L$9:$O$9))*50+50 -> 95.333333 | R17: =Q17*0.3 -> 28.6 | S17: 78 | T17: =S17/($S$9)*50+50 -> 98.75 | U17: =T17*0.5 -> 49.375 | V17: =SUM(U17,R17,K17,E17) -> 96.475 | W17: =IF(V17<74.5,"FAILED","PASSED") -> PASSED | Z17: 3 | AA17: 3 | AB17: 3 | AF17: =SUM(Z17:AE17) -> 9 | AG17: =(AF17/SUM($Z$9:$AE$9))*50+50 -> 100 | AH17: =AG17*0.1 -> 10 | AI17: 85 | AJ17: 75 | AO17: =SUM(AI17:AN17) -> 160 | AP17: =(AO17/SUM($AI$9:$AN$9))*50+50 -> 90 | AQ17: =AP17*0.4 -> 36 | AR17: 94 | AT17: =SUM(AR17:AS17) -> 94 | AU17: =(AT17/SUM($AR$9:$AS$9))*50+50 -> 97 | AV17: =AU17*0.5 -> 48.5 | AW17: =SUM(AV17,AQ17,AH17) -> 94.5 | AX17: =IF(AW17<74.5, "FAILED", "PASSED") -> PASSED | AZ17: =V17*0.6 -> 57.885 | BA17: =AW17*0.4 -> 37.8 | BB17: =SUM(AZ17:BA17) -> 95.685 | BC17: =IF(BB17<74.5,"FAILED","PASSED") -> PASSED
A18: =Attendance!A16 -> 9 | B18: =Attendance!B16 -> Banquil, Clarissa Marie Gonzaga | C18: =Attendance!S16 -> 3 | D18: =C18/3*50+50 -> 100 | E18: =D18*0.05 -> 5 | F18: 40 | I18: =SUM(F18:H18) -> 40 | J18: =(I18/SUM($F$9:$H$9))*50+50 -> 90 | K18: =J18*0.15 -> 13.5 | L18: 10 | M18: 8 | N18: 43 | P18: =SUM(L18:O18) -> 61 | Q18: =(P18/SUM($L$9:$O$9))*50+50 -> 90.666667 | R18: =Q18*0.3 -> 27.2 | S18: 68 | T18: =S18/($S$9)*50+50 -> 92.5 | U18: =T18*0.5 -> 46.25 | V18: =SUM(U18,R18,K18,E18) -> 91.95 | W18: =IF(V18<74.5,"FAILED","PASSED") -> PASSED | Z18: 3 | AA18: 3 | AB18: 3 | AF18: =SUM(Z18:AE18) -> 9 | AG18: =(AF18/SUM($Z$9:$AE$9))*50+50 -> 100 | AH18: =AG18*0.1 -> 10 | AI18: 88 | AJ18: 75 | AO18: =SUM(AI18:AN18) -> 163 | AP18: =(AO18/SUM($AI$9:$AN$9))*50+50 -> 90.75 | AQ18: =AP18*0.4 -> 36.3 | AR18: 88 | AT18: =SUM(AR18:AS18) -> 88 | AU18: =(AT18/SUM($AR$9:$AS$9))*50+50 -> 94 | AV18: =AU18*0.5 -> 47 | AW18: =SUM(AV18,AQ18,AH18) -> 93.3 | AX18: =IF(AW18<74.5, "FAILED", "PASSED") -> PASSED | AZ18: =V18*0.6 -> 55.17 | BA18: =AW18*0.4 -> 37.32 | BB18: =SUM(AZ18:BA18) -> 92.49 | BC18: =IF(BB18<74.5,"FAILED","PASSED") -> PASSED
A19: =Attendance!A17 -> 10 | B19: =Attendance!B17 -> Bas, Disney Claire Barde | C19: =Attendance!S17 -> 3 | D19: =C19/3*50+50 -> 100 | E19: =D19*0.05 -> 5 | F19: 40 | I19: =SUM(F19:H19) -> 40 | J19: =(I19/SUM($F$9:$H$9))*50+50 -> 90 | K19: =J19*0.15 -> 13.5 | L19: 13 | M19: 9 | N19: 44 | P19: =SUM(L19:O19) -> 66 | Q19: =(P19/SUM($L$9:$O$9))*50+50 -> 94 | R19: =Q19*0.3 -> 28.2 | S19: 77 | T19: =S19/($S$9)*50+50 -> 98.125 | U19: =T19*0.5 -> 49.0625 | V19: =SUM(U19,R19,K19,E19) -> 95.7625 | W19: =IF(V19<74.5,"FAILED","PASSED") -> PASSED | Z19: 3 | AA19: 3 | AB19: 3 | AF19: =SUM(Z19:AE19) -> 9 | AG19: =(AF19/SUM($Z$9:$AE$9))*50+50 -> 100 | AH19: =AG19*0.1 -> 10 | AI19: 75 | AJ19: 88 | AO19: =SUM(AI19:AN19) -> 163 | AP19: =(AO19/SUM($AI$9:$AN$9))*50+50 -> 90.75 | AQ19: =AP19*0.4 -> 36.3 | AR19: 91 | AT19: =SUM(AR19:AS19) -> 91 | AU19: =(AT19/SUM($AR$9:$AS$9))*50+50 -> 95.5 | AV19: =AU19*0.5 -> 47.75 | AW19: =SUM(AV19,AQ19,AH19) -> 94.05 | AX19: =IF(AW19<74.5, "FAILED", "PASSED") -> PASSED | AZ19: =V19*0.6 -> 57.4575 | BA19: =AW19*0.4 -> 37.62 | BB19: =SUM(AZ19:BA19) -> 95.0775 | BC19: =IF(BB19<74.5,"FAILED","PASSED") -> PASSED
A20: =Attendance!A18 -> 11 | B20: =Attendance!B18 -> Baynosa, Paul Yvanne Alinday | C20: =Attendance!S18 -> 1 | D20: =C20/3*50+50 -> 66.666667 | E20: =D20*0.05 -> 3.3333333 | F20: 40 | I20: =SUM(F20:H20) -> 40 | J20: =(I20/SUM($F$9:$H$9))*50+50 -> 90 | K20: =J20*0.15 -> 13.5 | L20: 9 | M20: 0 | N20: 41 | P20: =SUM(L20:O20) -> 50 | Q20: =(P20/SUM($L$9:$O$9))*50+50 -> 83.333333 | R20: =Q20*0.3 -> 25 | S20: 40 | T20: =S20/($S$9)*50+50 -> 75 | U20: =T20*0.5 -> 37.5 | V20: =SUM(U20,R20,K20,E20) -> 79.333333 | W20: =IF(V20<74.5,"FAILED","PASSED") -> PASSED | Z20: 0 | AA20: 3 | AB20: 0 | AF20: =SUM(Z20:AE20) -> 3 | AG20: =(AF20/SUM($Z$9:$AE$9))*50+50 -> 66.666667 | AH20: =AG20*0.1 -> 6.6666667 | AI20: 0 | AJ20: 0 | AO20: =SUM(AI20:AN20) -> 0 | AP20: =(AO20/SUM($AI$9:$AN$9))*50+50 -> 50 | AQ20: =AP20*0.4 -> 20 | AR20: 91 | AT20: =SUM(AR20:AS20) -> 91 | AU20: =(AT20/SUM($AR$9:$AS$9))*50+50 -> 95.5 | AV20: =AU20*0.5 -> 47.75 | AW20: =SUM(AV20,AQ20,AH20) -> 74.416667 | AX20: =IF(AW20<74.5, "FAILED", "PASSED") -> FAILED | AZ20: =V20*0.6 -> 47.6 | BA20: =AW20*0.4 -> 29.766667 | BB20: =SUM(AZ20:BA20) -> 77.366667 | BC20: =IF(BB20<74.5,"FAILED","PASSED") -> PASSED
A21: =Attendance!A19 -> 12 | B21: =Attendance!B19 -> Benig, Timothy Jade Crave | C21: =Attendance!S19 -> 1 | D21: =C21/3*50+50 -> 66.666667 | E21: =D21*0.05 -> 3.3333333 | F21: 40 | I21: =SUM(F21:H21) -> 40 | J21: =(I21/SUM($F$9:$H$9))*50+50 -> 90 | K21: =J21*0.15 -> 13.5 | L21: 10 | M21: 0 | N21: 45 | P21: =SUM(L21:O21) -> 55 | Q21: =(P21/SUM($L$9:$O$9))*50+50 -> 86.666667 | R21: =Q21*0.3 -> 26 | S21: 75 | T21: =S21/($S$9)*50+50 -> 96.875 | U21: =T21*0.5 -> 48.4375 | V21: =SUM(U21,R21,K21,E21) -> 91.270833 | W21: =IF(V21<74.5,"FAILED","PASSED") -> PASSED | Z21: 0 | AA21: 3 | AB21: 0 | AF21: =SUM(Z21:AE21) -> 3 | AG21: =(AF21/SUM($Z$9:$AE$9))*50+50 -> 66.666667 | AH21: =AG21*0.1 -> 6.6666667 | AI21: 0 | AJ21: 0 | AO21: =SUM(AI21:AN21) -> 0 | AP21: =(AO21/SUM($AI$9:$AN$9))*50+50 -> 50 | AQ21: =AP21*0.4 -> 20 | AR21: 88 | AT21: =SUM(AR21:AS21) -> 88 | AU21: =(AT21/SUM($AR$9:$AS$9))*50+50 -> 94 | AV21: =AU21*0.5 -> 47 | AW21: =SUM(AV21,AQ21,AH21) -> 73.666667 | AX21: =IF(AW21<74.5, "FAILED", "PASSED") -> FAILED | AZ21: =V21*0.6 -> 54.7625 | BA21: =AW21*0.4 -> 29.466667 | BB21: =SUM(AZ21:BA21) -> 84.229167 | BC21: =IF(BB21<74.5,"FAILED","PASSED") -> PASSED
... A54: =Attendance!A52 -> 45 | B54: =Attendance!B52 -> Verial, Marlou Cebuco | C54: =Attendance!S52 -> 0 | D54: =C54/3*50+50 -> 50 | E54: =D54*0.05 -> 2.5 | F54: 0 | I54: =SUM(F54:H54) -> 0 | J54: =(I54/SUM($F$9:$H$9))*50+50 -> 50 | K54: =J54*0.15 -> 7.5 | L54: 0 | M54: 0 | N54: 38 | P54: =SUM(L54:O54) -> 38 | Q54: =(P54/SUM($L$9:$O$9))*50+50 -> 75.333333 | R54: =Q54*0.3 -> 22.6 | S54: 43 | T54: =S54/($S$9)*50+50 -> 76.875 | U54: =T54*0.5 -> 38.4375 | V54: =SUM(U54,R54,K54,E54) -> 71.0375 | W54: =IF(V54<74.5,"FAILED","PASSED") -> FAILED | Z54: 0 | AA54: 0 | AB54: 0 | AF54: =SUM(Z54:AE54) -> 0 | AG54: =(AF54/SUM($Z$9:$AE$9))*50+50 -> 50 | AH54: =AG54*0.1 -> 5 | AI54: 0 | AJ54: 0 | AO54: =SUM(AI54:AN54) -> 0 | AP54: =(AO54/SUM($AI$9:$AN$9))*50+50 -> 50 | AQ54: =AP54*0.4 -> 20 | AR54: 0 | AT54: =SUM(AR54:AS54) -> 0 | AU54: =(AT54/SUM($AR$9:$AS$9))*50+50 -> 50 | AV54: =AU54*0.5 -> 25 | AW54: =SUM(AV54,AQ54,AH54) -> 50 | AX54: =IF(AW54<74.5, "FAILED", "PASSED") -> FAILED | AZ54: =V54*0.6 -> 42.6225 | BA54: =AW54*0.4 -> 20 | BB54: =SUM(AZ54:BA54) -> 62.6225 | BC54: =IF(BB54<74.5,"FAILED","PASSED") -> FAILED

Sheet Final
B1: =Attendance!B1 -> SUBJECT: IS 2
B2: =Attendance!B2 -> COURSE/YEAR: BSIT 1D | C2: FINAL GRADE
B3: =Attendance!B3 -> TIME: 1:00 PM - 5:00 PM
B4: =Attendance!B4 -> ROOM: COMPLAB 4
B5: =Attendance!B5 -> UNITS: 2
C6: LECTURE | Z6: LABORATORY | AZ6: TOTAL GRADE
C7: ATTENDANCE | F7: ASSIGNMENT/SEATWORK | L7: QUIZZES | S7: EXAM | V7: PRELIM GRADE | W7: REMARKS | Z7: ATTENDANCE | AI7: LABORATORY EXERCISES | AR7: LABORATORY ASSESSMENT | AW7: PRELIM GRADE | AX7: REMARKS | AZ7: LECTURE GRADE | BA7: LAB. GRADE | BB7: PRELIM GRADE | BC7: REMARKS
C8: 0.05 | F8: 0.15 | L8: 0.3 | S8: 0.5 | Z8: 0.1 | AI8: 0.4 | AR8: 0.5
A9: No. | B9: Student Name | C9: 3 | D9: =C9/3*50+50 -> 100 | E9: =D9*0.05 -> 5 | F9: 50 | I9: =SUM(F9:H9) -> 50 | J9: =(I9/SUM($F$9:$H$9))*50+50 -> 100 | K9: =J9*0.15 -> 15 | L9: 15 | M9: 15 | N9: 10 | P9: =SUM(L9:O9) -> 40 | Q9: =(P9/SUM($L$9:$O$9))*50+50 -> 100 | R9: =Q9*0.3 -> 30 | S9: 80 | T9: =S9/($S$9)*50+50 -> 100 | U9: =T9*0.5 -> 50 | V9: =SUM(U9,R9,K9,E9) -> 100 | Z9: 3 | AA9: 3 | AB9: 3 | AF9: =SUM(Z9:AE9) -> 9 | AG9: =(AF9/SUM($Z$9:$AE$9))*50+50 -> 100 | AH9: =AG9*0.1 -> 10 | AI9: 100 | AJ9: 100 | AK9: 100 | AO9: =SUM(AI9:AN9) -> 300 | AP9: =(AO9/SUM($AI$9:$AN$9))*50+50 -> 100 | AQ9: =AP9*0.4 -> 40 | AR9: 100 | AT9: =SUM(AR9:AS9) -> 100 | AU9: =(AT9/SUM($AR$9:$AS$9))*50+50 -> 100 | AV9: =AU9*0.5 -> 50 | AW9: =SUM(AV9,AQ9,AH9) -> 100 | AZ9: =V9*0.6 -> 60 | BA9: =AW9*0.4 -> 40 | BB9: =SUM(AZ9:BA9) -> 100 | BC9: =IF(BB9<74.5,"FAILED","PASSED") -> PASSED
A10: =Attendance!A8 -> 1 | B10: Alcantara, Albert Marquez | C10: =Attendance!AB8 -> 3 | D10: =C10/3*50+50 -> 100 | E10: =D10*0.05 -> 5 | F10: 35 | I10: =SUM(F10:H10) -> 35 | J10: =(I10/SUM($F$9:$H$9))*50+50 -> 85 | K10: =J10*0.15 -> 12.75 | L10: 10 | M10: 5 | N10: 6 | P10: =SUM(L10:O10) -> 21 | Q10: =(P10/SUM($L$9:$O$9))*50+50 -> 76.25 | R10: =Q10*0.3 -> 22.875 | S10: 45 | T10: =S10/($S$9)*50+50 -> 78.125 | U10: =T10*0.5 -> 39.0625 | V10: =SUM(U10,R10,K10,E10) -> 79.6875 | W10: =IF(V10<74.5,"FAILED","PASSED") -> PASSED | Z10: 3 | AA10: 3 | AB10: 3 | AF10: =SUM(Z10:AE10) -> 9 | AG10: =(AF10/SUM($Z$9:$AE$9))*50+50 -> 100 | AH10: =AG10*0.1 -> 10 | AI10: 95 | AJ10: 90 | AK10: 90 | AO10: =SUM(AI10:AN10) -> 275 | AP10: =(AO10/SUM($AI$9:$AN$9))*50+50 -> 95.833333 | AQ10: =AP10*0.4 -> 38.333333 | AR10: 80 | AT10: =SUM(AR10:AS10) -> 80 | AU10: =(AT10/SUM($AR$9:$AS$9))*50+50 -> 90 | AV10: =AU10*0.5 -> 45 | AW10: =SUM(AV10,AQ10,AH10) -> 93.333333 | AX10: =IF(AW10<74.5, "FAILED", "PASSED") -> PASSED | AZ10: =V10*0.6 -> 47.8125 | BA10: =AW10*0.4 -> 37.333333 | BB10: =SUM(AZ10:BA10) -> 85.145833 | BC10: =IF(BB10<74.5,"FAILED","PASSED") -> PASSED
A11: =Attendance!A9 -> 2 | B11: Aliaga, Rence Carl Medeloso | C11: =Attendance!AB9 -> 3 | D11: =C11/3*50+50 -> 100 | E11: =D11*0.05 -> 5 | F11: 35 | I11: =SUM(F11:H11) -> 35 | J11: =(I11/SUM($F$9:$H$9))*50+50 -> 85 | K11: =J11*0.15 -> 12.75 | L11: 10 | M11: 9 | N11: 7 | P11: =SUM(L11:O11) -> 26 | Q11: =(P11/SUM($L$9:$O$9))*50+50 -> 82.5 | R11: =Q11*0.3 -> 24.75 | S11: 34 | T11: =S11/($S$9)*50+50 -> 71.25 | U11: =T11*0.5 -> 35.625 | V11: =SUM(U11,R11,K11,E11) -> 78.125 | W11: =IF(V11<74.5,"FAILED","PASSED") -> PASSED | Z11: 0 | AA11: 0 | AB11: 0 | AF11: =SUM(Z11:AE11) -> 0 | AG11: =(AF11/SUM($Z$9:$AE$9))*50+50 -> 50 | AH11: =AG11*0.1 -> 5 | AI11: 0 | AJ11: 0 | AK11: 0 | AO11: =SUM(AI11:AN11) -> 0 | AP11: =(AO11/SUM($AI$9:$AN$9))*50+50 -> 50 | AQ11: =AP11*0.4 -> 20 | AR11: 80 | AT11: =SUM(AR11:AS11) -> 80 | AU11: =(AT11/SUM($AR$9:$AS$9))*50+50 -> 90 | AV11: =AU11*0.5 -> 45 | AW11: =SUM(AV11,AQ11,AH11) -> 70 | AX11: =IF(AW11<74.5, "FAILED", "PASSED") -> FAILED | AZ11: =V11*0.6 -> 46.875 | BA11: =AW11*0.4 -> 28 | BB11: =SUM(AZ11:BA11) -> 74.875 | BC11: =IF(BB11<74.5,"FAILED","PASSED") -> PASSED
A12: =Attendance!A10 -> 3 | B12: Almirol, Rheyjan Collado | C12: =Attendance!AB10 -> 3 | D12: =C12/3*50+50 -> 100 | E12: =D12*0.05 -> 5 | F12: 35 | I12: =SUM(F12:H12) -> 35 | J12: =(I12/SUM($F$9:$H$9))*50+50 -> 85 | K12: =J12*0.15 -> 12.75 | L12: 8 | M12: 7 | N12: 6 | P12: =SUM(L12:O12) -> 21 | Q12: =(P12/SUM($L$9:$O$9))*50+50 -> 76.25 | R12: =Q12*0.3 -> 22.875 | S12: 43 | T12: =S12/($S$9)*50+50 -> 76.875 | U12: =T12*0.5 -> 38.4375 | V12: =SUM(U12,R12,K12,E12) -> 79.0625 | W12: =IF(V12<74.5,"FAILED","PASSED") -> PASSED | Z12: 3 | AA12: 3 | AB12: 3 | AF12: =SUM(Z12:AE12) -> 9 | AG12: =(AF12/SUM($Z$9:$AE$9))*50+50 -> 100 | AH12: =AG12*0.1 -> 10 | AI12: 75 | AJ12: 80 | AK12: 85 | AO12: =SUM(AI12:AN12) -> 240 | AP12: =(AO12/SUM($AI$9:$AN$9))*50+50 -> 90 | AQ12: =AP12*0.4 -> 36 | AR12: 80 | AT12: =SUM(AR12:AS12) -> 80 | AU12: =(AT12/SUM($AR$9:$AS$9))*50+50 -> 90 | AV12: =AU12*0.5 -> 45 | AW12: =SUM(AV12,AQ12,AH12) -> 91 | AX12: =IF(AW12<74.5, "FAILED", "PASSED") -> PASSED | AZ12: =V12*0.6 -> 47.4375 | BA12: =AW12*0.4 -> 36.4 | BB12: =SUM(AZ12:BA12) -> 83.8375 | BC12: =IF(BB12<74.5,"FAILED","PASSED") -> PASSED
A13: =Attendance!A11 -> 4 | B13: Andiano, Noel Rabago | C13: =Attendance!AB11 -> 3 | D13: =C13/3*50+50 -> 100 | E13: =D13*0.05 -> 5 | F13: 35 | I13: =SUM(F13:H13) -> 35 | J13: =(I13/SUM($F$9:$H$9))*50+50 -> 85 | K13: =J13*0.15 -> 12.75 | L13: 3 | M13: 2 | N13: 1 | P13: =SUM(L13:O13) -> 6 | Q13: =(P13/SUM($L$9:$O$9))*50+50 -> 57.5 | R13: =Q13*0.3 -> 17.25 | S13: 26 | T13: =S13/($S$9)*50+50 -> 66.25 | U13: =T13*0.5 -> 33.125 | V13: =SUM(U13,R13,K13,E13) -> 68.125 | W13: =IF(V13<74.5,"FAILED","PASSED") -> FAILED | Z13: 0 | AA13: 0 | AB13: 0 | AF13: =SUM(Z13:AE13) -> 0 | AG13: =(AF13/SUM($Z$9:$AE$9))*50+50 -> 50 | AH13: =AG13*0.1 -> 5 | AI13: 0 | AJ13: 0 | AK13: 0 | AO13: =SUM(AI13:AN13) -> 0 | AP13: =(AO13/SUM($AI$9:$AN$9))*50+50 -> 50 | AQ13: =AP13*0.4 -> 20 | AR13: 80 | AT13: =SUM(AR13:AS13) -> 80 | AU13: =(AT13/SUM($AR$9:$AS$9))*50+50 -> 90 | AV13: =AU13*0.5 -> 45 | AW13: =SUM(AV13,AQ13,AH13) -> 70 | AX13: =IF(AW13<74.5, "FAILED", "PASSED") -> FAILED | AZ13: =V13*0.6 -> 40.875 | BA13: =AW13*0.4 -> 28 | BB13: =SUM(AZ13:BA13) -> 68.875 | BC13: =IF(BB13<74.5,"FAILED","PASSED") -> FAILED
A14: =Attendance!A12 -> 5 | B14: Ante, Clyde Mhyco Mendoza | C14: =Attendance!AB12 -> 0 | D14: =C14/3*50+50 -> 50 | E14: =D14*0.05 -> 2.5 | F14: 35 | I14: =SUM(F14:H14) -> 35 | J14: =(I14/SUM($F$9:$H$9))*50+50 -> 85 | K14: =J14*0.15 -> 12.75 | L14: 0 | M14: 0 | N14: 0 | P14: =SUM(L14:O14) -> 0 | Q14: =(P14/SUM($L$9:$O$9))*50+50 -> 50 | R14: =Q14*0.3 -> 15 | S14: 29 | T14: =S14/($S$9)*50+50 -> 68.125 | U14: =T14*0.5 -> 34.0625 | V14: =SUM(U14,R14,K14,E14) -> 64.3125 | W14: =IF(V14<74.5,"FAILED","PASSED") -> FAILED | Z14: 0 | AA14: 0 | AB14: 0 | AF14: =SUM(Z14:AE14) -> 0 | AG14: =(AF14/SUM($Z$9:$AE$9))*50+50 -> 50 | AH14: =AG14*0.1 -> 5 | AI14: 0 | AJ14: 0 | AK14: 0 | AO14: =SUM(AI14:AN14) -> 0 | AP14: =(AO14/SUM($AI$9:$AN$9))*50+50 -> 50 | AQ14: =AP14*0.4 -> 20 | AR14: 80 | AT14: =SUM(AR14:AS14) -> 80 | AU14: =(AT14/SUM($AR$9:$AS$9))*50+50 -> 90 | AV14: =AU14*0.5 -> 45 | AW14: =SUM(AV14,AQ14,AH14) -> 70 | AX14: =IF(AW14<74.5, "FAILED", "PASSED") -> FAILED | AZ14: =V14*0.6 -> 38.5875 | BA14: =AW14*0.4 -> 28 | BB14: =SUM(AZ14:BA14) -> 66.5875 | BC14: =IF(BB14<74.5,"FAILED","PASSED") -> FAILED
A15: =Attendance!A13 -> 6 | B15: Antiporda, Jay Mark Cabes | C15: =Attendance!AB13 -> 3 | D15: =C15/3*50+50 -> 100 | E15: =D15*0.05 -> 5 | F15: 35 | I15: =SUM(F15:H15) -> 35 | J15: =(I15/SUM($F$9:$H$9))*50+50 -> 85 | K15: =J15*0.15 -> 12.75 | L15: 10 | M15: 11 | N15: 8 | P15: =SUM(L15:O15) -> 29 | Q15: =(P15/SUM($L$9:$O$9))*50+50 -> 86.25 | R15: =Q15*0.3 -> 25.875 | S15: 35 | T15: =S15/($S$9)*50+50 -> 71.875 | U15: =T15*0.5 -> 35.9375 | V15: =SUM(U15,R15,K15,E15) -> 79.5625 | W15: =IF(V15<74.5,"FAILED","PASSED") -> PASSED | Z15: 3 | AA15: 3 | AB15: 3 | AF15: =SUM(Z15:AE15) -> 9 | AG15: =(AF15/SUM($Z$9:$AE$9))*50+50 -> 100 | AH15: =AG15*0.1 -> 10 | AI15: 95 | AJ15: 98 | AK15: 90 | AO15: =SUM(AI15:AN15) -> 283 | AP15: =(AO15/SUM($AI$9:$AN$9))*50+50 -> 97.166667 | AQ15: =AP15*0.4 -> 38.866667 | AR15: 80 | AT15: =SUM(AR15:AS15) -> 80 | AU15: =(AT15/SUM($AR$9:$AS$9))*50+50 -> 90 | AV15: =AU15*0.5 -> 45 | AW15: =SUM(AV15,AQ15,AH15) -> 93.866667 | AX15: =IF(AW15<74.5, "FAILED", "PASSED") -> PASSED | AZ15: =V15*0.6 -> 47.7375 | BA15: =AW15*0.4 -> 37.546667 | BB15: =SUM(AZ15:BA15) -> 85.284167 | BC15: =IF(BB15<74.5,"FAILED","PASSED") -> PASSED
A16: =Attendance!A14 -> 7 | B16: Aragon, Jaspher Hanly Tejada | C16: =Attendance!AB14 -> 0 | D16: =C16/3*50+50 -> 50 | E16: =D16*0.05 -> 2.5 | F16: 35 | I16: =SUM(F16:H16) -> 35 | J16: =(I16/SUM($F$9:$H$9))*50+50 -> 85 | K16: =J16*0.15 -> 12.75 | L16: 0 | M16: 0 | N16: 0 | P16: =SUM(L16:O16) -> 0 | Q16: =(P16/SUM($L$9:$O$9))*50+50 -> 50 | R16: =Q16*0.3 -> 15 | S16: 47 | T16: =S16/($S$9)*50+50 -> 79.375 | U16: =T16*0.5 -> 39.6875 | V16: =SUM(U16,R16,K16,E16) -> 69.9375 | W16: =IF(V16<74.5,"FAILED","PASSED") -> FAILED | Z16: 3 | AA16: 3 | AB16: 3 | AF16: =SUM(Z16:AE16) -> 9 | AG16: =(AF16/SUM($Z$9:$AE$9))*50+50 -> 100 | AH16: =AG16*0.1 -> 10 | AI16: 95 | AJ16: 95 | AK16: 90 | AO16: =SUM(AI16:AN16) -> 280 | AP16: =(AO16/SUM($AI$9:$AN$9))*50+50 -> 96.666667 | AQ16: =AP16*0.4 -> 38.666667 | AR16: 80 | AT16: =SUM(AR16:AS16) -> 80 | AU16: =(AT16/SUM($AR$9:$AS$9))*50+50 -> 90 | AV16: =AU16*0.5 -> 45 | AW16: =SUM(AV16,AQ16,AH16) -> 93.666667 | AX16: =IF(AW16<74.5, "FAILED", "PASSED") -> PASSED | AZ16: =V16*0.6 -> 41.9625 | BA16: =AW16*0.4 -> 37.466667 | BB16: =SUM(AZ16:BA16) -> 79.429167 | BC16: =IF(BB16<74.5,"FAILED","PASSED") -> PASSED
A17: =Attendance!A15 -> 8 | B17: Armada, Donie Lagania | C17: =Attendance!AB15 -> 3 | D17: =C17/3*50+50 -> 100 | E17: =D17*0.05 -> 5 | F17: 35 | I17: =SUM(F17:H17) -> 35 | J17: =(I17/SUM($F$9:$H$9))*50+50 -> 85 | K17: =J17*0.15 -> 12.75 | L17: 11 | M17: 11 | N17: 7 | P17: =SUM(L17:O17) -> 29 | Q17: =(P17/SUM($L$9:$O$9))*50+50 -> 86.25 | R17: =Q17*0.3 -> 25.875 | S17: 61 | T17: =S17/($S$9)*50+50 -> 88.125 | U17: =T17*0.5 -> 44.0625 | V17: =SUM(U17,R17,K17,E17) -> 87.6875 | W17: =IF(V17<74.5,"FAILED","PASSED") -> PASSED | Z17: 0 | AA17: 0 | AB17: 0 | AF17: =SUM(Z17:AE17) -> 0 | AG17: =(AF17/SUM($Z$9:$AE$9))*50+50 -> 50 | AH17: =AG17*0.1 -> 5 | AI17: 0 | AJ17: 0 | AK17: 0 | AO17: =SUM(AI17:AN17) -> 0 | AP17: =(AO17/SUM($AI$9:$AN$9))*50+50 -> 50 | AQ17: =AP17*0.4 -> 20 | AR17: 80 | AT17: =SUM(AR17:AS17) -> 80 | AU17: =(AT17/SUM($AR$9:$AS$9))*50+50 -> 90 | AV17: =AU17*0.5 -> 45 | AW17: =SUM(AV17,AQ17,AH17) -> 70 | AX17: =IF(AW17<74.5, "FAILED", "PASSED") -> FAILED | AZ17: =V17*0.6 -> 52.6125 | BA17: =AW17*0.4 -> 28 | BB17: =SUM(AZ17:BA17) -> 80.6125 | BC17: =IF(BB17<74.5,"FAILED","PASSED") -> PASSED
A18: =Attendance!A16 -> 9 | B18: Banquil, Clarissa Marie Gonzaga | C18: =Attendance!AB16 -> 3 | D18: =C18/3*50+50 -> 100 | E18: =D18*0.05 -> 5 | F18: 35 | I18: =SUM(F18:H18) -> 35 | J18: =(I18/SUM($F$9:$H$9))*50+50 -> 85 | K18: =J18*0.15 -> 12.75 | L18: 8 | M18: 11 | N18: 8 | P18: =SUM(L18:O18) -> 27 | Q18: =(P18/SUM($L$9:$O$9))*50+50 -> 83.75 | R18: =Q18*0.3 -> 25.125 | S18: 46 | T18: =S18/($S$9)*50+50 -> 78.75 | U18: =T18*0.5 -> 39.375 | V18: =SUM(U18,R18,K18,E18) -> 82.25 | W18: =IF(V18<74.5,"FAILED","PASSED") -> PASSED | Z18: 3 | AA18: 3 | AB18: 3 | AF18: =SUM(Z18:AE18) -> 9 | AG18: =(AF18/SUM($Z$9:$AE$9))*50+50 -> 100 | AH18: =AG18*0.1 -> 10 | AI18: 85 | AJ18: 85 | AK18: 85 | AO18: =SUM(AI18:AN18) -> 255 | AP18: =(AO18/SUM($AI$9:$AN$9))*50+50 -> 92.5 | AQ18: =AP18*0.4 -> 37 | AR18: 80 | AT18: =SUM(AR18:AS18) -> 80 | AU18: =(AT18/SUM($AR$9:$AS$9))*50+50 -> 90 | AV18: =AU18*0.5 -> 45 | AW18: =SUM(AV18,AQ18,AH18) -> 92 | AX18: =IF(AW18<74.5, "FAILED", "PASSED") -> PASSED | AZ18: =V18*0.6 -> 49.35 | BA18: =AW18*0.4 -> 36.8 | BB18: =SUM(AZ18:BA18) -> 86.15 | BC18: =IF(BB18<74.5,"FAILED","PASSED") -> PASSED
A19: =Attendance!A17 -> 10 | B19: Bas, Disney Claire Barde | C19: =Attendance!AB17 -> 3 | D19: =C19/3*50+50 -> 100 | E19: =D19*0.05 -> 5 | F19: 35 | I19: =SUM(F19:H19) -> 35 | J19: =(I19/SUM($F$9:$H$9))*50+50 -> 85 | K19: =J19*0.15 -> 12.75 | L19: 9 | M19: 11 | N19: 9 | P19: =SUM(L19:O19) -> 29 | Q19: =(P19/SUM($L$9:$O$9))*50+50 -> 86.25 | R19: =Q19*0.3 -> 25.875 | S19: 48 | T19: =S19/($S$9)*50+50 -> 80 | U19: =T19*0.5 -> 40 | V19: =SUM(U19,R19,K19,E19) -> 83.625 | W19: =IF(V19<74.5,"FAILED","PASSED") -> PASSED | Z19: 3 | AA19: 3 | AB19: 3 | AF19: =SUM(Z19:AE19) -> 9 | AG19: =(AF19/SUM($Z$9:$AE$9))*50+50 -> 100 | AH19: =AG19*0.1 -> 10 | AI19: 100 | AJ19: 90 | AK19: 95 | AO19: =SUM(AI19:AN19) -> 285 | AP19: =(AO19/SUM($AI$9:$AN$9))*50+50 -> 97.5 | AQ19: =AP19*0.4 -> 39 | AR19: 80 | AT19: =SUM(AR19:AS19) -> 80 | AU19: =(AT19/SUM($AR$9:$AS$9))*50+50 -> 90 | AV19: =AU19*0.5 -> 45 | AW19: =SUM(AV19,AQ19,AH19) -> 94 | AX19: =IF(AW19<74.5, "FAILED", "PASSED") -> PASSED | AZ19: =V19*0.6 -> 50.175 | BA19: =AW19*0.4 -> 37.6 | BB19: =SUM(AZ19:BA19) -> 87.775 | BC19: =IF(BB19<74.5,"FAILED","PASSED") -> PASSED
A20: =Attendance!A18 -> 11 | B20: Baynosa, Paul Yvanne Alinday | C20: =Attendance!AB18 -> 0 | D20: =C20/3*50+50 -> 50 | E20: =D20*0.05 -> 2.5 | F20: 35 | I20: =SUM(F20:H20) -> 35 | J20: =(I20/SUM($F$9:$H$9))*50+50 -> 85 | K20: =J20*0.15 -> 12.75 | L20: 0 | M20: 0 | N20: 0 | P20: =SUM(L20:O20) -> 0 | Q20: =(P20/SUM($L$9:$O$9))*50+50 -> 50 | R20: =Q20*0.3 -> 15 | S20: 41 | T20: =S20/($S$9)*50+50 -> 75.625 | U20: =T20*0.5 -> 37.8125 | V20: =SUM(U20,R20,K20,E20) -> 68.0625 | W20: =IF(V20<74.5,"FAILED","PASSED") -> FAILED | Z20: 0 | AA20: 0 | AB20: 0 | AF20: =SUM(Z20:AE20) -> 0 | AG20: =(AF20/SUM($Z$9:$AE$9))*50+50 -> 50 | AH20: =AG20*0.1 -> 5 | AI20: 0 | AJ20: 0 | AK20: 0 | AO20: =SUM(AI20:AN20) -> 0 | AP20: =(AO20/SUM($AI$9:$AN$9))*50+50 -> 50 | AQ20: =AP20*0.4 -> 20 | AR20: 80 | AT20: =SUM(AR20:AS20) -> 80 | AU20: =(AT20/SUM($AR$9:$AS$9))*50+50 -> 90 | AV20: =AU20*0.5 -> 45 | AW20: =SUM(AV20,AQ20,AH20) -> 70 | AX20: =IF(AW20<74.5, "FAILED", "PASSED") -> FAILED | AZ20: =V20*0.6 -> 40.8375 | BA20: =AW20*0.4 -> 28 | BB20: =SUM(AZ20:BA20) -> 68.8375 | BC20: =IF(BB20<74.5,"FAILED","PASSED") -> FAILED
A21: =Attendance!A19 -> 12 | B21: Benig, Timothy Jade Crave | C21: =Attendance!AB19 -> 0 | D21: =C21/3*50+50 -> 50 | E21: =D21*0.05 -> 2.5 | F21: 35 | I21: =SUM(F21:H21) -> 35 | J21: =(I21/SUM($F$9:$H$9))*50+50 -> 85 | K21: =J21*0.15 -> 12.75 | L21: 0 | M21: 0 | N21: 0 | P21: =SUM(L21:O21) -> 0 | Q21: =(P21/SUM($L$9:$O$9))*50+50 -> 50 | R21: =Q21*0.3 -> 15 | S21: 46 | T21: =S21/($S$9)*50+50 -> 78.75 | U21: =T21*0.5 -> 39.375 | V21: =SUM(U21,R21,K21,E21) -> 69.625 | W21: =IF(V21<74.5,"FAILED","PASSED") -> FAILED | Z21: 0 | AA21: 0 | AB21: 0 | AF21: =SUM(Z21:AE21) -> 0 | AG21: =(AF21/SUM($Z$9:$AE$9))*50+50 -> 50 | AH21: =AG21*0.1 -> 5 | AI21: 0 | AJ21: 0 | AK21: 0 | AO21: =SUM(AI21:AN21) -> 0 | AP21: =(AO21/SUM($AI$9:$AN$9))*50+50 -> 50 | AQ21: =AP21*0.4 -> 20 | AR21: 80 | AT21: =SUM(AR21:AS21) -> 80 | AU21: =(AT21/SUM($AR$9:$AS$9))*50+50 -> 90 | AV21: =AU21*0.5 -> 45 | AW21: =SUM(AV21,AQ21,AH21) -> 70 | AX21: =IF(AW21<74.5, "FAILED", "PASSED") -> FAILED | AZ21: =V21*0.6 -> 41.775 | BA21: =AW21*0.4 -> 28 | BB21: =SUM(AZ21:BA21) -> 69.775 | BC21: =IF(BB21<74.5,"FAILED","PASSED") -> FAILED
... A52: =Attendance!A50 -> 43 | B52: Trespeses, Reykarl Pendon | C52: =Attendance!AB50 -> 0 | D52: =C52/3*50+50 -> 50 | E52: =D52*0.05 -> 2.5 | F52: 0 | I52: =SUM(F52:H52) -> 0 | J52: =(I52/SUM($F$9:$H$9))*50+50 -> 50 | K52: =J52*0.15 -> 7.5 | L52: 0 | M52: 0 | N52: 0 | P52: =SUM(L52:O52) -> 0 | Q52: =(P52/SUM($L$9:$O$9))*50+50 -> 50 | R52: =Q52*0.3 -> 15 | S52: 0 | T52: =S52/($S$9)*50+50 -> 50 | U52: =T52*0.5 -> 25 | V52: =SUM(U52,R52,K52,E52) -> 50 | W52: =IF(V52<74.5,"FAILED","PASSED") -> FAILED | Z52: 0 | AA52: 0 | AB52: 0 | AF52: =SUM(Z52:AE52) -> 0 | AG52: =(AF52/SUM($Z$9:$AE$9))*50+50 -> 50 | AH52: =AG52*0.1 -> 5 | AI52: 0 | AJ52: 0 | AK52: 0 | AO52: =SUM(AI52:AN52) -> 0 | AP52: =(AO52/SUM($AI$9:$AN$9))*50+50 -> 50 | AQ52: =AP52*0.4 -> 20 | AR52: 0 | AT52: =SUM(AR52:AS52) -> 0 | AU52: =(AT52/SUM($AR$9:$AS$9))*50+50 -> 50 | AV52: =AU52*0.5 -> 25 | AW52: =SUM(AV52,AQ52,AH52) -> 50 | AX52: =IF(AW52<74.5, "FAILED", "PASSED") -> FAILED | AZ52: =V52*0.6 -> 30 | BA52: =AW52*0.4 -> 20 | BB52: =SUM(AZ52:BA52) -> 50 | BC52: =IF(BB52<74.5,"FAILED","PASSED") -> FAILED
A53: 44 | B53: Tuloganon, Raffy Verano | C53: =Attendance!AB51 -> 3 | D53: =C53/3*50+50 -> 100 | E53: =D53*0.05 -> 5 | F53: 35 | I53: =SUM(F53:H53) -> 35 | J53: =(I53/SUM($F$9:$H$9))*50+50 -> 85 | K53: =J53*0.15 -> 12.75 | L53: 7 | M53: 13 | N53: 6 | P53: =SUM(L53:O53) -> 26 | Q53: =(P53/SUM($L$9:$O$9))*50+50 -> 82.5 | R53: =Q53*0.3 -> 24.75 | S53: 43 | T53: =S53/($S$9)*50+50 -> 76.875 | U53: =T53*0.5 -> 38.4375 | V53: =SUM(U53,R53,K53,E53) -> 80.9375 | W53: =IF(V53<74.5,"FAILED","PASSED") -> PASSED | Z53: 3 | AA53: 3 | AB53: 3 | AF53: =SUM(Z53:AE53) -> 9 | AG53: =(AF53/SUM($Z$9:$AE$9))*50+50 -> 100 | AH53: =AG53*0.1 -> 10 | AI53: 80 | AJ53: 90 | AK53: 90 | AO53: =SUM(AI53:AN53) -> 260 | AP53: =(AO53/SUM($AI$9:$AN$9))*50+50 -> 93.333333 | AQ53: =AP53*0.4 -> 37.333333 | AR53: 80 | AT53: =SUM(AR53:AS53) -> 80 | AU53: =(AT53/SUM($AR$9:$AS$9))*50+50 -> 90 | AV53: =AU53*0.5 -> 45 | AW53: =SUM(AV53,AQ53,AH53) -> 92.333333 | AX53: =IF(AW53<74.5, "FAILED", "PASSED") -> PASSED | AZ53: =V53*0.6 -> 48.5625 | BA53: =AW53*0.4 -> 36.933333 | BB53: =SUM(AZ53:BA53) -> 85.495833 | BC53: =IF(BB53<74.5,"FAILED","PASSED") -> PASSED
A54: 45 | B54: Verial, Marlou Cebuco | C54: =Attendance!AB52 -> 0 | D54: =C54/3*50+50 -> 50 | E54: =D54*0.05 -> 2.5 | F54: 35 | I54: =SUM(F54:H54) -> 35 | J54: =(I54/SUM($F$9:$H$9))*50+50 -> 85 | K54: =J54*0.15 -> 12.75 | L54: 0 | M54: 0 | N54: 0 | P54: =SUM(L54:O54) -> 0 | Q54: =(P54/SUM($L$9:$O$9))*50+50 -> 50 | R54: =Q54*0.3 -> 15 | S54: 0 | T54: =S54/($S$9)*50+50 -> 50 | U54: =T54*0.5 -> 25 | V54: =SUM(U54,R54,K54,E54) -> 55.25 | W54: =IF(V54<74.5,"FAILED","PASSED") -> FAILED | Z54: 0 | AA54: 0 | AB54: 0 | AF54: =SUM(Z54:AE54) -> 0 | AG54: =(AF54/SUM($Z$9:$AE$9))*50+50 -> 50 | AH54: =AG54*0.1 -> 5 | AI54: 0 | AJ54: 0 | AK54: 0 | AO54: =SUM(AI54:AN54) -> 0 | AP54: =(AO54/SUM($AI$9:$AN$9))*50+50 -> 50 | AQ54: =AP54*0.4 -> 20 | AR54: 80 | AT54: =SUM(AR54:AS54) -> 80 | AU54: =(AT54/SUM($AR$9:$AS$9))*50+50 -> 90 | AV54: =AU54*0.5 -> 45 | AW54: =SUM(AV54,AQ54,AH54) -> 70 | AX54: =IF(AW54<74.5, "FAILED", "PASSED") -> FAILED | AZ54: =V54*0.6 -> 33.15 | BA54: =AW54*0.4 -> 28 | BB54: =SUM(AZ54:BA54) -> 61.15 | BC54: =IF(BB54<74.5,"FAILED","PASSED") -> FAILED

Sheet IS 2 FINAL GRADE
B1: =Attendance!B1 -> SUBJECT: IS 2
B2: =Attendance!B2 -> COURSE/YEAR: BSIT 1D
B3: =Attendance!B3 -> TIME: 1:00 PM - 5:00 PM
B4: =Attendance!B4 -> ROOM: COMPLAB 4
B5: =Attendance!B5 -> UNITS: 2
A7: =Attendance!A7 -> No. | B7: =Attendance!B7 -> Student Name | C7: PRELIM | D7: MIDTERM | E7: FINAL | F7: FINAL GRADE | G7: REMARKS
A8: =Attendance!A8 -> 1 | B8: =Attendance!B8 -> Alcantara, Albert Marquez | C8: =Prelim!BB10 -> 83.475 | D8: =Midterm!BB10 -> 87.223333 | E8: =Final!BB10 -> 85.145833 | F8: =AVERAGE(C8:E8) -> 85.281389 | G8: =IF(F8<74.5,"FAILED","PASSED") -> PASSED
A9: =Attendance!A9 -> 2 | B9: =Attendance!B9 -> Aliaga, Rence Carl Medeloso | C9: =Prelim!BB11 -> 88 | D9: =Midterm!BB11 -> 85.648333 | E9: =Final!BB11 -> 74.875 | F9: =AVERAGE(C9:E9) -> 82.841111 | G9: =IF(F9<74.5,"FAILED","PASSED") -> PASSED
A10: =Attendance!A10 -> 3 | B10: =Attendance!B10 -> Almirol, Rheyjan Collado | C10: =Prelim!BB12 -> 77.1125 | D10: =Midterm!BB12 -> 89.59 | E10: =Final!BB12 -> 83.8375 | F10: =AVERAGE(C10:E10) -> 83.513333 | G10: =IF(F10<74.5,"FAILED","PASSED") -> PASSED
A11: =Attendance!A11 -> 4 | B11: =Attendance!B11 -> Andiano, Noel Rabago | C11: =Prelim!BB13 -> 86.025 | D11: =Midterm!BB13 -> 82.660833 | E11: =Final!BB13 -> 68.875 | F11: =AVERAGE(C11:E11) -> 79.186944 | G11: =IF(F11<74.5,"FAILED","PASSED") -> PASSED
A12: =Attendance!A12 -> 5 | B12: =Attendance!B12 -> Ante, Clyde Mhyco Mendoza | C12: =Prelim!BB14 -> 76.825 | D12: =Midterm!BB14 -> 67.979167 | E12: =Final!BB14 -> 66.5875 | F12: =AVERAGE(C12:E12) -> 70.463889 | G12: =IF(F12<74.5,"FAILED","PASSED") -> FAILED
A13: =Attendance!A13 -> 6 | B13: =Attendance!B13 -> Antiporda, Jay Mark Cabes | C13: =Prelim!BB15 -> 91.625 | D13: =Midterm!BB15 -> 89.155 | E13: =Final!BB15 -> 85.284167 | F13: =AVERAGE(C13:E13) -> 88.688056 | G13: =IF(F13<74.5,"FAILED","PASSED") -> PASSED
A14: =Attendance!A14 -> 7 | B14: =Attendance!B14 -> Aragon, Jaspher Hanly Tejada | C14: =Prelim!BB16 -> 90.8375 | D14: =Midterm!BB16 -> 91.47 | E14: =Final!BB16 -> 79.429167 | F14: =AVERAGE(C14:E14) -> 87.245556 | G14: =IF(F14<74.5,"FAILED","PASSED") -> PASSED
A15: =Attendance!A15 -> 8 | B15: =Attendance!B15 -> Armada, Donie Lagania | C15: =Prelim!BB17 -> 94.2625 | D15: =Midterm!BB17 -> 95.685 | E15: =Final!BB17 -> 80.6125 | F15: =AVERAGE(C15:E15) -> 90.186667 | G15: =IF(F15<74.5,"FAILED","PASSED") -> PASSED
A16: =Attendance!A16 -> 9 | B16: =Attendance!B16 -> Banquil, Clarissa Marie Gonzaga | C16: =Prelim!BB18 -> 94.025 | D16: =Midterm!BB18 -> 92.49 | E16: =Final!BB18 -> 86.15 | F16: =AVERAGE(C16:E16) -> 90.888333 | G16: =IF(F16<74.5,"FAILED","PASSED") -> PASSED
A17: =Attendance!A17 -> 10 | B17: =Attendance!B17 -> Bas, Disney Claire Barde | C17: =Prelim!BB19 -> 95.8875 | D17: =Midterm!BB19 -> 95.0775 | E17: =Final!BB19 -> 87.775 | F17: =AVERAGE(C17:E17) -> 92.913333 | G17: =IF(F17<74.5,"FAILED","PASSED") -> PASSED
A18: =Attendance!A18 -> 11 | B18: =Attendance!B18 -> Baynosa, Paul Yvanne Alinday | C18: =Prelim!BB20 -> 89.525 | D18: =Midterm!BB20 -> 77.366667 | E18: =Final!BB20 -> 68.8375 | F18: =AVERAGE(C18:E18) -> 78.576389 | G18: =IF(F18<74.5,"FAILED","PASSED") -> PASSED
A19: =Attendance!A19 -> 12 | B19: =Attendance!B19 -> Benig, Timothy Jade Crave | C19: =Prelim!BB21 -> 90.3625 | D19: =Midterm!BB21 -> 84.229167 | E19: =Final!BB21 -> 69.775 | F19: =AVERAGE(C19:E19) -> 81.455556 | G19: =IF(F19<74.5,"FAILED","PASSED") -> PASSED
A20: =Attendance!A20 -> 13 | B20: =Attendance!B20 -> Bolambao, Elaiza Claire Umbay | C20: =Prelim!BB22 -> 93.225 | D20: =Midterm!BB22 -> 90.49 | E20: =Final!BB22 -> 68.95 | F20: =AVERAGE(C20:E20) -> 84.221667 | G20: =IF(F20<74.5,"FAILED","PASSED") -> PASSED
A21: =Attendance!A21 -> 14 | B21: =Attendance!B21 -> Bulado, Dexter Camillo | C21: =Prelim!BB23 -> 77.275 | D21: =Midterm!BB23 -> 78.046667 | E21: 65 | F21: =AVERAGE(C21:E21) -> 73.440556 | G21: =IF(F21<74.5,"FAILED","PASSED") -> FAILED
A22: =Attendance!A22 -> 15 | B22: =Attendance!B22 -> Cagang, Anjune Carcueva | C22: =Prelim!BB24 -> 94.6875 | D22: =Midterm!BB24 -> 92.3025 | E22: =Final!BB24 -> 82.133333 | F22: =AVERAGE(C22:E22) -> 89.707778 | G22: =IF(F22<74.5,"FAILED","PASSED") -> PASSED
A23: =Attendance!A23 -> 16 | B23: =Attendance!B23 -> Datuin, Francis Carl Mag-aso | C23: =Prelim!BB25 -> 84.5625 | D23: =Midterm!BB25 -> 79.711667 | E23: =Final!BB25 -> 76.354167 | F23: =AVERAGE(C23:E23) -> 80.209444 | G23: =IF(F23<74.5,"FAILED","PASSED") -> PASSED
A24: =Attendance!A24 -> 17 | B24: =Attendance!B24 -> Detoperez, Knytz Panizales | C24: =Prelim!BB26 -> 82.2125 | D24: =Midterm!BB26 -> 92.235 | E24: =Final!BB26 -> 83.720833 | F24: =AVERAGE(C24:E24) -> 86.056111 | G24: =IF(F24<74.5,"FAILED","PASSED") -> PASSED
A25: =Attendance!A25 -> 18 | B25: =Attendance!B25 -> Dilanggalen, Hanz Amher Rollo | C25: =Prelim!BB27 -> 93.8125 | D25: =Midterm!BB27 -> 88.755 | E25: =Final!BB27 -> 85.038333 | F25: =AVERAGE(C25:E25) -> 89.201944 | G25: =IF(F25<74.5,"FAILED","PASSED") -> PASSED
A26: =Attendance!A26 -> 19 | B26: =Attendance!B26 -> Domingo, Arsenio Jr. Dioleste | C26: =Prelim!BB28 -> 94.65 | D26: =Midterm!BB28 -> 93.765 | E26: =Final!BB28 -> 85.291667 | F26: =AVERAGE(C26:E26) -> 91.235556 | G26: =IF(F26<74.5,"FAILED","PASSED") -> PASSED
